Workbook

Sheet OverallResult
A1: BANGALORE INSTITUTE OF TECHNOLOGY
A2: (Affiliated to Visvesvaraya Technological University, Belagavi, Recognised by AICTE, New Delhi) K.R. Road, V.V. Pura, Bengaluru – 560 004. Phone: 26613237/26615865 Fax: 22426796
A3: Provisional Results of Second Semester 2022 Batch Examination for the Academic year 2023-24 (Sep/Oct 2023)
A4: Department of CSE-Data Science
D6: Mathematics for CSE Stream -II (BMATS201) | N6: Chemistry for CSE Stream (BCHES202) | W6: Computer-Aided Engineering Drawing (BCEDK203) | AF6: Introduction to Electronics Communication (BESCK204C) | AO6: Introduction to Python Programming (BPLCK205B) | AX6: Professional Writing Skills in English (BPWSK206) | BG6: Samskrutika Kannada / Balake Kannada (BKSKK207 / BKBKK207) | BP6: Scientific Foundations of Health (BSFHK2058)
A7: Sl.No | B7: USN | C7: Student Name | D7: Section | E7: IN | F7: EX | G7: RV | H7: T | I7: CR | J7: GP | K7: GR | L7: CR*GP | N7: IN | O7: EX | P7: RV | Q7: T | R7: CR | S7: GP | T7: GR | U7: CR*GP | W7: IA | X7: EX | Y7: RV | Z7: T | AA7: CR | AB7: GP | AC7: GR | AD7: CR*GP | AF7: IA | AG7: EX | AH7: RV | AI7: T | AJ7: CR | AK7: GP | AL7: GR | AM7: CR*GP | AO7: IA | AP7: EX | AQ7: RV | AR7: T | AS7: CR | AT7: GP | AU7: GR | AV7: CR*GP | AX7: IA | AY7: EX | AZ7: RV | BA7: T | BB7: CR | BC7: GP | BD7: GR | BE7: CR*GP | BG7: IA | BH7: EX | BI7: RV | BJ7: T | BK7: CR | BL7: GP | BM7: GR | BN7: CR*GP | BP7: IA | BQ7: EX | BR7: RV | BS7: T | BT7: CR | BU7: GP | BV7: GR | BW7: CR*GP | CA7: SGPA | CB7: Final Grade | CC7: Percentage | CE7: Total Marks | CF7: Percentage
A8: 1 | B8: 1BI23CD001 | C8: ALTAF MAKASHI | D8: D | E8: 45 | F8: 35 | H8: =SUM(E8:F8) -> 80 | I8: 4 | J8: =IF(F8<=17,"0",IF(H8<=39,"0",IF(H8<=49,"4",IF(H8<=54,"5",IF(H8<=59,"6",IF(H8<=69,"7",IF(H8<=79,"8",IF(H8<=89,"9","10")))))))) -> 9 | K8: =IF(F8<=17,"F",IF(H8<=39,"F",IF(H8<=49,"P",IF(H8<=54,"C",IF(H8<=59,"B",IF(H8<=69,"B+",IF(H8<=79,"A",IF(H8<=89,"A+","O")))))))) -> A+ | L8: =I8*J8 -> 36 | Q8: =SUM(N8:O8) -> 0 | R8: 4 | S8: =IF(O8<=17,"0",IF(Q8<=39,"4",IF(Q8<=49,"4",IF(Q8<=54,"5",IF(Q8<=59,"6",IF(Q8<=69,"7",IF(Q8<=79,"8",IF(Q8<=89,"9","10")))))))) -> 0 | T8: =IF(O8<=17,"F",IF(Q8<=39,"F",IF(Q8<=49,"P",IF(Q8<=54,"C",IF(Q8<=59,"B",IF(Q8<=69,"B+",IF(Q8<=79,"A",IF(Q8<=89,"A+","O")))))))) -> F | U8: =R8*S8 -> 0 | Z8: =SUM(W8:X8) -> 0 | AA8: 3 | AB8: =IF(X8<=17,"0",IF(Z8<=39,"0",IF(Z8<=49,"4",IF(Z8<=54,"5",IF(Z8<=59,"6",IF(Z8<=69,"7",IF(Z8<=79,"8",IF(Z8<=89,"9","10")))))))) -> 0 | AC8: =IF(X8<=17,"F",IF(Z8<=39,"F",IF(Z8<=49,"P",IF(Z8<=54,"C",IF(Z8<=59,"B",IF(Z8<=69,"B+",IF(Z8<=79,"A",IF(Z8<=89,"A+","O")))))))) -> F | AD8: =AA8*AB8 -> 0 | AI8: =SUM(AF8:AG8) -> 0 | AJ8: 3 | AK8: =IF(AG8<=17,"0",IF(AI8<=39,"0",IF(AI8<=49,"4",IF(AI8<=54,"5",IF(AI8<=59,"6",IF(AI8<=69,"7",IF(AI8<=79,"8",IF(AI8<=89,"9","10")))))))) -> 0 | AL8: =IF(AG8<=17,"F",IF(AI8<=39,"F",IF(AI8<=49,"P",IF(AI8<=54,"C",IF(AI8<=59,"B",IF(AI8<=69,"B+",IF(AI8<=79,"A",IF(AI8<=89,"A+","O")))))))) -> F | AM8: =AJ8*AK8 -> 0 | AR8: =(AO8+AP8) -> 0 | AS8: 3 | AT8: =IF(AP8<=17,"0",IF(AR8<=39,"0",IF(AR8<=49,"4",IF(AR8<=54,"5",IF(AR8<=59,"6",IF(AR8<=69,"7",IF(AR8<=79,"8",IF(AR8<=89,"9","10")))))))) -> 0 | AU8: =IF(AP8<=17,"F",IF(AR8<=39,"F",IF(AR8<=49,"P",IF(AR8<=54,"C",IF(AR8<=59,"B",IF(AR8<=69,"B+",IF(AR8<=79,"A",IF(AR8<=89,"A+","O")))))))) -> F | AV8: =AS8*AT8 -> 0 | BA8: =(AX8+AY8) -> 0 | BB8: 1 | BC8: =IF(AY8<=17,"0",IF(BA8<=39,"0",IF(BA8<=49,"4",IF(BA8<=54,"5",IF(BA8<=59,"6",IF(BA8<=69,"7",IF(BA8<=79,"8",IF(BA8<=89,"9","10")))))))) -> 0 | BD8: =IF(AY8<=17,"F",IF(BA8<=39,"F",IF(BA8<=49,"P",IF(BA8<=54,"C",IF(BA8<=59,"B",IF(BA8<=69,"B+",IF(BA8<=79,"A",IF(BA8<=89,"A+","O")))))))) -> F | BE8: =BB8*BC8 -> 0 | BF8: Balake Kannada | BJ8: =(BG8+BH8) -> 0 | BK8: 1 | BL8: =IF(BH8<=17,"0",IF(BJ8<=39,"0",IF(BJ8<=49,"4",IF(BJ8<=54,"5",IF(BJ8<=59,"6",IF(BJ8<=69,"7",IF(BJ8<=79,"8",IF(BJ8<=89,"9","10")))))))) -> 0 | BM8: =IF(BH8<=17,"F",IF(BJ8<=39,"F",IF(BJ8<=49,"P",IF(BJ8<=54,"C",IF(BJ8<=59,"B",IF(BJ8<=69,"B+",IF(BJ8<=79,"A",IF(BJ8<=89,"A+","O")))))))) -> F | BN8: =BK8*BL8 -> 0 | BS8: =(BP8+BQ8) -> 0 | BT8: 1 | BU8: =IF(BQ8<=17,"0",IF(BS8<=39,"0",IF(BS8<=49,"4",IF(BS8<=54,"5",IF(BS8<=59,"6",IF(BS8<=69,"7",IF(BS8<=79,"8",IF(BS8<=89,"9","10")))))))) -> 0 | BV8: =IF(BQ8<=17,"F",IF(BS8<=39,"F",IF(BS8<=49,"P",IF(BS8<=54,"C",IF(BS8<=59,"B",IF(BS8<=69,"B+",IF(BS8<=79,"A",IF(BS8<=89,"A+","O")))))))) -> F | BW8: =BT8*BU8 -> 0 | BZ8: =L8+U8+AD8+AM8+AV8+BE8+BN8+BW8 -> 36 | CA8: =BZ8/20 -> 1.8 | CB8: =IF(CA8<4,"F",IF(BV8="F","F",IF(BM8="F","F",IF(BD8="F","F",IF(AU8="F","F",IF(AL8="F","F",IF(AC8="F","F",IF(T8="F","F",IF(K8="F","F",IF(CA8<=5,"C",IF(CA8<6,"B",IF(CA8<7,"B+",IF(CA8<8,"A",IF(CA8<=9,"A+","O")))))))))))))) -> F | CC8: =CA8*9.5 -> 17.1 | CE8: =SUM(BS8,BJ8,BA8,AR8,AI8,Z8,Q8,H8) -> 80 | CF8: =(CE8/800)*100 -> 10 | CI8: =IF(CA8<=4,"F",IF(CA8<=6,"PASS",IF(CA8<=6.5,"SC",IF(CA8<=7.5,"FC",IF(CA8<="10","FCD"))))) -> F
A9: =A8+1 -> 2 | B9: 1BI23CD002 | C9: ANJALI M | D9: D | H9: =SUM(E9:F9) -> 0 | I9: 4 | J9: =IF(F9<=17,"0",IF(H9<=39,"0",IF(H9<=49,"4",IF(H9<=54,"5",IF(H9<=59,"6",IF(H9<=69,"7",IF(H9<=79,"8",IF(H9<=89,"9","10")))))))) -> 0 | K9: =IF(F9<=17,"F",IF(H9<=39,"F",IF(H9<=49,"P",IF(H9<=54,"C",IF(H9<=59,"B",IF(H9<=69,"B+",IF(H9<=79,"A",IF(H9<=89,"A+","O")))))))) -> F | L9: =I9*J9 -> 0 | Q9: =SUM(N9:O9) -> 0 | R9: 4 | S9: =IF(O9<=17,"0",IF(Q9<=39,"4",IF(Q9<=49,"4",IF(Q9<=54,"5",IF(Q9<=59,"6",IF(Q9<=69,"7",IF(Q9<=79,"8",IF(Q9<=89,"9","10")))))))) -> 0 | T9: =IF(O9<=17,"F",IF(Q9<=39,"F",IF(Q9<=49,"P",IF(Q9<=54,"C",IF(Q9<=59,"B",IF(Q9<=69,"B+",IF(Q9<=79,"A",IF(Q9<=89,"A+","O")))))))) -> F | U9: =R9*S9 -> 0 | Z9: =SUM(W9:X9) -> 0 | AA9: 3 | AB9: =IF(X9<=17,"0",IF(Z9<=39,"0",IF(Z9<=49,"4",IF(Z9<=54,"5",IF(Z9<=59,"6",IF(Z9<=69,"7",IF(Z9<=79,"8",IF(Z9<=89,"9","10")))))))) -> 0 | AC9: =IF(X9<=17,"F",IF(Z9<=39,"F",IF(Z9<=49,"P",IF(Z9<=54,"C",IF(Z9<=59,"B",IF(Z9<=69,"B+",IF(Z9<=79,"A",IF(Z9<=89,"A+","O")))))))) -> F | AD9: =AA9*AB9 -> 0 | AI9: =SUM(AF9:AG9) -> 0 | AJ9: 3 | AK9: =IF(AG9<=17,"0",IF(AI9<=39,"0",IF(AI9<=49,"4",IF(AI9<=54,"5",IF(AI9<=59,"6",IF(AI9<=69,"7",IF(AI9<=79,"8",IF(AI9<=89,"9","10")))))))) -> 0 | AL9: =IF(AG9<=17,"F",IF(AI9<=39,"F",IF(AI9<=49,"P",IF(AI9<=54,"C",IF(AI9<=59,"B",IF(AI9<=69,"B+",IF(AI9<=79,"A",IF(AI9<=89,"A+","O")))))))) -> F | AM9: =AJ9*AK9 -> 0 | AR9: =(AO9+AP9) -> 0 | AS9: 3 | AT9: =IF(AP9<=17,"0",IF(AR9<=39,"0",IF(AR9<=49,"4",IF(AR9<=54,"5",IF(AR9<=59,"6",IF(AR9<=69,"7",IF(AR9<=79,"8",IF(AR9<=89,"9","10")))))))) -> 0 | AU9: =IF(AP9<=17,"F",IF(AR9<=39,"F",IF(AR9<=49,"P",IF(AR9<=54,"C",IF(AR9<=59,"B",IF(AR9<=69,"B+",IF(AR9<=79,"A",IF(AR9<=89,"A+","O")))))))) -> F | AV9: =AS9*AT9 -> 0 | BA9: =(AX9+AY9) -> 0 | BB9: 1 | BC9: =IF(AY9<=17,"0",IF(BA9<=39,"0",IF(BA9<=49,"4",IF(BA9<=54,"5",IF(BA9<=59,"6",IF(BA9<=69,"7",IF(BA9<=79,"8",IF(BA9<=89,"9","10")))))))) -> 0 | BD9: =IF(AY9<=17,"F",IF(BA9<=39,"F",IF(BA9<=49,"P",IF(BA9<=54,"C",IF(BA9<=59,"B",IF(BA9<=69,"B+",IF(BA9<=79,"A",IF(BA9<=89,"A+","O")))))))) -> F | BE9: =BB9*BC9 -> 0 | BF9: Samskrutika Kannada | BJ9: =(BG9+BH9) -> 0 | BK9: 1 | BL9: =IF(BH9<=17,"0",IF(BJ9<=39,"0",IF(BJ9<=49,"4",IF(BJ9<=54,"5",IF(BJ9<=59,"6",IF(BJ9<=69,"7",IF(BJ9<=79,"8",IF(BJ9<=89,"9","10")))))))) -> 0 | BM9: =IF(BH9<=17,"F",IF(BJ9<=39,"F",IF(BJ9<=49,"P",IF(BJ9<=54,"C",IF(BJ9<=59,"B",IF(BJ9<=69,"B+",IF(BJ9<=79,"A",IF(BJ9<=89,"A+","O")))))))) -> F | BN9: =BK9*BL9 -> 0 | BS9: =(BP9+BQ9) -> 0 | BT9: 1 | BU9: =IF(BQ9<=17,"0",IF(BS9<=39,"0",IF(BS9<=49,"4",IF(BS9<=54,"5",IF(BS9<=59,"6",IF(BS9<=69,"7",IF(BS9<=79,"8",IF(BS9<=89,"9","10")))))))) -> 0 | BV9: =IF(BQ9<=17,"F",IF(BS9<=39,"F",IF(BS9<=49,"P",IF(BS9<=54,"C",IF(BS9<=59,"B",IF(BS9<=69,"B+",IF(BS9<=79,"A",IF(BS9<=89,"A+","O")))))))) -> F | BW9: =BT9*BU9 -> 0 | BZ9: =L9+U9+AD9+AM9+AV9+BE9+BN9+BW9 -> 0 | CA9: =BZ9/20 -> 0 | CB9: =IF(CA9<4,"F",IF(BV9="F","F",IF(BM9="F","F",IF(BD9="F","F",IF(AU9="F","F",IF(AL9="F","F",IF(AC9="F","F",IF(T9="F","F",IF(K9="F","F",IF(CA9<=5,"C",IF(CA9<6,"B",IF(CA9<7,"B+",IF(CA9<8,"A",IF(CA9<=9,"A+","O")))))))))))))) -> F | CC9: =CA9*9.5 -> 0 | CE9: =SUM(BS9,BJ9,BA9,AR9,AI9,Z9,Q9,H9) -> 0 | CF9: =(CE9/800)*100 -> 0 | CI9: =IF(CA9<=4,"F",IF(CA9<=6,"PASS",IF(CA9<=6.5,"SC",IF(CA9<=7.5,"FC",IF(CA9<="10","FCD"))))) -> F
A10: =A9+1 -> 3 | B10: 1BI23CD003 | C10: ANKIT KUMAR | D10: D | H10: =SUM(E10:F10) -> 0 | I10: 4 | J10: =IF(F10<=17,"0",IF(H10<=39,"0",IF(H10<=49,"4",IF(H10<=54,"5",IF(H10<=59,"6",IF(H10<=69,"7",IF(H10<=79,"8",IF(H10<=89,"9","10")))))))) -> 0 | K10: =IF(F10<=17,"F",IF(H10<=39,"F",IF(H10<=49,"P",IF(H10<=54,"C",IF(H10<=59,"B",IF(H10<=69,"B+",IF(H10<=79,"A",IF(H10<=89,"A+","O")))))))) -> F | L10: =I10*J10 -> 0 | Q10: =SUM(N10:O10) -> 0 | R10: 4 | S10: =IF(O10<=17,"0",IF(Q10<=39,"4",IF(Q10<=49,"4",IF(Q10<=54,"5",IF(Q10<=59,"6",IF(Q10<=69,"7",IF(Q10<=79,"8",IF(Q10<=89,"9","10")))))))) -> 0 | T10: =IF(O10<=17,"F",IF(Q10<=39,"F",IF(Q10<=49,"P",IF(Q10<=54,"C",IF(Q10<=59,"B",IF(Q10<=69,"B+",IF(Q10<=79,"A",IF(Q10<=89,"A+","O")))))))) -> F | U10: =R10*S10 -> 0 | Z10: =SUM(W10:X10) -> 0 | AA10: 3 | AB10: =IF(X10<=17,"0",IF(Z10<=39,"0",IF(Z10<=49,"4",IF(Z10<=54,"5",IF(Z10<=59,"6",IF(Z10<=69,"7",IF(Z10<=79,"8",IF(Z10<=89,"9","10")))))))) -> 0 | AC10: =IF(X10<=17,"F",IF(Z10<=39,"F",IF(Z10<=49,"P",IF(Z10<=54,"C",IF(Z10<=59,"B",IF(Z10<=69,"B+",IF(Z10<=79,"A",IF(Z10<=89,"A+","O")))))))) -> F | AD10: =AA10*AB10 -> 0 | AI10: =SUM(AF10:AG10) -> 0 | AJ10: 3 | AK10: =IF(AG10<=17,"0",IF(AI10<=39,"0",IF(AI10<=49,"4",IF(AI10<=54,"5",IF(AI10<=59,"6",IF(AI10<=69,"7",IF(AI10<=79,"8",IF(AI10<=89,"9","10")))))))) -> 0 | AL10: =IF(AG10<=17,"F",IF(AI10<=39,"F",IF(AI10<=49,"P",IF(AI10<=54,"C",IF(AI10<=59,"B",IF(AI10<=69,"B+",IF(AI10<=79,"A",IF(AI10<=89,"A+","O")))))))) -> F | AM10: =AJ10*AK10 -> 0 | AR10: =(AO10+AP10) -> 0 | AS10: 3 | AT10: =IF(AP10<=17,"0",IF(AR10<=39,"0",IF(AR10<=49,"4",IF(AR10<=54,"5",IF(AR10<=59,"6",IF(AR10<=69,"7",IF(AR10<=79,"8",IF(AR10<=89,"9","10")))))))) -> 0 | AU10: =IF(AP10<=17,"F",IF(AR10<=39,"F",IF(AR10<=49,"P",IF(AR10<=54,"C",IF(AR10<=59,"B",IF(AR10<=69,"B+",IF(AR10<=79,"A",IF(AR10<=89,"A+","O")))))))) -> F | AV10: =AS10*AT10 -> 0 | BA10: =(AX10+AY10) -> 0 | BB10: 1 | BC10: =IF(AY10<=17,"0",IF(BA10<=39,"0",IF(BA10<=49,"4",IF(BA10<=54,"5",IF(BA10<=59,"6",IF(BA10<=69,"7",IF(BA10<=79,"8",IF(BA10<=89,"9","10")))))))) -> 0 | BD10: =IF(AY10<=17,"F",IF(BA10<=39,"F",IF(BA10<=49,"P",IF(BA10<=54,"C",IF(BA10<=59,"B",IF(BA10<=69,"B+",IF(BA10<=79,"A",IF(BA10<=89,"A+","O")))))))) -> F | BE10: =BB10*BC10 -> 0 | BF10: Balake Kannada | BJ10: =(BG10+BH10) -> 0 | BK10: 1 | BL10: =IF(BH10<=17,"0",IF(BJ10<=39,"0",IF(BJ10<=49,"4",IF(BJ10<=54,"5",IF(BJ10<=59,"6",IF(BJ10<=69,"7",IF(BJ10<=79,"8",IF(BJ10<=89,"9","10")))))))) -> 0 | BM10: =IF(BH10<=17,"F",IF(BJ10<=39,"F",IF(BJ10<=49,"P",IF(BJ10<=54,"C",IF(BJ10<=59,"B",IF(BJ10<=69,"B+",IF(BJ10<=79,"A",IF(BJ10<=89,"A+","O")))))))) -> F | BN10: =BK10*BL10 -> 0 | BS10: =(BP10+BQ10) -> 0 | BT10: 1 | BU10: =IF(BQ10<=17,"0",IF(BS10<=39,"0",IF(BS10<=49,"4",IF(BS10<=54,"5",IF(BS10<=59,"6",IF(BS10<=69,"7",IF(BS10<=79,"8",IF(BS10<=89,"9","10")))))))) -> 0 | BV10: =IF(BQ10<=17,"F",IF(BS10<=39,"F",IF(BS10<=49,"P",IF(BS10<=54,"C",IF(BS10<=59,"B",IF(BS10<=69,"B+",IF(BS10<=79,"A",IF(BS10<=89,"A+","O")))))))) -> F | BW10: =BT10*BU10 -> 0 | BZ10: =L10+U10+AD10+AM10+AV10+BE10+BN10+BW10 -> 0 | CA10: =BZ10/20 -> 0 | CB10: =IF(CA10<4,"F",IF(BV10="F","F",IF(BM10="F","F",IF(BD10="F","F",IF(AU10="F","F",IF(AL10="F","F",IF(AC10="F","F",IF(T10="F","F",IF(K10="F","F",IF(CA10<=5,"C",IF(CA10<6,"B",IF(CA10<7,"B+",IF(CA10<8,"A",IF(CA10<=9,"A+","O")))))))))))))) -> F | CC10: =CA10*9.5 -> 0 | CE10: =SUM(BS10,BJ10,BA10,AR10,AI10,Z10,Q10,H10) -> 0 | CF10: =(CE10/800)*100 -> 0 | CI10: =IF(CA10<=4,"F",IF(CA10<=6,"PASS",IF(CA10<=6.5,"SC",IF(CA10<=7.5,"FC",IF(CA10<="10","FCD"))))) -> F
A11: =A10+1 -> 4 | B11: 1BI23CD004 | C11: ARYAN KASHYAP | D11: D | H11: =SUM(E11:F11) -> 0 | I11: 4 | J11: =IF(F11<=17,"0",IF(H11<=39,"0",IF(H11<=49,"4",IF(H11<=54,"5",IF(H11<=59,"6",IF(H11<=69,"7",IF(H11<=79,"8",IF(H11<=89,"9","10")))))))) -> 0 | K11: =IF(F11<=17,"F",IF(H11<=39,"F",IF(H11<=49,"P",IF(H11<=54,"C",IF(H11<=59,"B",IF(H11<=69,"B+",IF(H11<=79,"A",IF(H11<=89,"A+","O")))))))) -> F | L11: =I11*J11 -> 0 | Q11: =SUM(N11:O11) -> 0 | R11: 4 | S11: =IF(O11<=17,"0",IF(Q11<=39,"4",IF(Q11<=49,"4",IF(Q11<=54,"5",IF(Q11<=59,"6",IF(Q11<=69,"7",IF(Q11<=79,"8",IF(Q11<=89,"9","10")))))))) -> 0 | T11: =IF(O11<=17,"F",IF(Q11<=39,"F",IF(Q11<=49,"P",IF(Q11<=54,"C",IF(Q11<=59,"B",IF(Q11<=69,"B+",IF(Q11<=79,"A",IF(Q11<=89,"A+","O")))))))) -> F | U11: =R11*S11 -> 0 | Z11: =SUM(W11:X11) -> 0 | AA11: 3 | AB11: =IF(X11<=17,"0",IF(Z11<=39,"0",IF(Z11<=49,"4",IF(Z11<=54,"5",IF(Z11<=59,"6",IF(Z11<=69,"7",IF(Z11<=79,"8",IF(Z11<=89,"9","10")))))))) -> 0 | AC11: =IF(X11<=17,"F",IF(Z11<=39,"F",IF(Z11<=49,"P",IF(Z11<=54,"C",IF(Z11<=59,"B",IF(Z11<=69,"B+",IF(Z11<=79,"A",IF(Z11<=89,"A+","O")))))))) -> F | AD11: =AA11*AB11 -> 0 | AI11: =SUM(AF11:AG11) -> 0 | AJ11: 3 | AK11: =IF(AG11<=17,"0",IF(AI11<=39,"0",IF(AI11<=49,"4",IF(AI11<=54,"5",IF(AI11<=59,"6",IF(AI11<=69,"7",IF(AI11<=79,"8",IF(AI11<=89,"9","10")))))))) -> 0 | AL11: =IF(AG11<=17,"F",IF(AI11<=39,"F",IF(AI11<=49,"P",IF(AI11<=54,"C",IF(AI11<=59,"B",IF(AI11<=69,"B+",IF(AI11<=79,"A",IF(AI11<=89,"A+","O")))))))) -> F | AM11: =AJ11*AK11 -> 0 | AR11: =(AO11+AP11) -> 0 | AS11: 3 | AT11: =IF(AP11<=17,"0",IF(AR11<=39,"0",IF(AR11<=49,"4",IF(AR11<=54,"5",IF(AR11<=59,"6",IF(AR11<=69,"7",IF(AR11<=79,"8",IF(AR11<=89,"9","10")))))))) -> 0 | AU11: =IF(AP11<=17,"F",IF(AR11<=39,"F",IF(AR11<=49,"P",IF(AR11<=54,"C",IF(AR11<=59,"B",IF(AR11<=69,"B+",IF(AR11<=79,"A",IF(AR11<=89,"A+","O")))))))) -> F | AV11: =AS11*AT11 -> 0 | BA11: =(AX11+AY11) -> 0 | BB11: 1 | BC11: =IF(AY11<=17,"0",IF(BA11<=39,"0",IF(BA11<=49,"4",IF(BA11<=54,"5",IF(BA11<=59,"6",IF(BA11<=69,"7",IF(BA11<=79,"8",IF(BA11<=89,"9","10")))))))) -> 0 | BD11: =IF(AY11<=17,"F",IF(BA11<=39,"F",IF(BA11<=49,"P",IF(BA11<=54,"C",IF(BA11<=59,"B",IF(BA11<=69,"B+",IF(BA11<=79,"A",IF(BA11<=89,"A+","O")))))))) -> F | BE11: =BB11*BC11 -> 0 | BF11: Samskrutika Kannada | BJ11: =(BG11+BH11) -> 0 | BK11: 1 | BL11: =IF(BH11<=17,"0",IF(BJ11<=39,"0",IF(BJ11<=49,"4",IF(BJ11<=54,"5",IF(BJ11<=59,"6",IF(BJ11<=69,"7",IF(BJ11<=79,"8",IF(BJ11<=89,"9","10")))))))) -> 0 | BM11: =IF(BH11<=17,"F",IF(BJ11<=39,"F",IF(BJ11<=49,"P",IF(BJ11<=54,"C",IF(BJ11<=59,"B",IF(BJ11<=69,"B+",IF(BJ11<=79,"A",IF(BJ11<=89,"A+","O")))))))) -> F | BN11: =BK11*BL11 -> 0 | BS11: =(BP11+BQ11) -> 0 | BT11: 1 | BU11: =IF(BQ11<=17,"0",IF(BS11<=39,"0",IF(BS11<=49,"4",IF(BS11<=54,"5",IF(BS11<=59,"6",IF(BS11<=69,"7",IF(BS11<=79,"8",IF(BS11<=89,"9","10")))))))) -> 0 | BV11: =IF(BQ11<=17,"F",IF(BS11<=39,"F",IF(BS11<=49,"P",IF(BS11<=54,"C",IF(BS11<=59,"B",IF(BS11<=69,"B+",IF(BS11<=79,"A",IF(BS11<=89,"A+","O")))))))) -> F | BW11: =BT11*BU11 -> 0 | BZ11: =L11+U11+AD11+AM11+AV11+BE11+BN11+BW11 -> 0 | CA11: =BZ11/20 -> 0 | CB11: =IF(CA11<4,"F",IF(BV11="F","F",IF(BM11="F","F",IF(BD11="F","F",IF(AU11="F","F",IF(AL11="F","F",IF(AC11="F","F",IF(T11="F","F",IF(K11="F","F",IF(CA11<=5,"C",IF(CA11<6,"B",IF(CA11<7,"B+",IF(CA11<8,"A",IF(CA11<=9,"A+","O")))))))))))))) -> F | CC11: =CA11*9.5 -> 0 | CE11: =SUM(BS11,BJ11,BA11,AR11,AI11,Z11,Q11,H11) -> 0 | CF11: =(CE11/800)*100 -> 0 | CI11: F
A12: =A11+1 -> 5 | B12: 1BI23CD005 | C12: ARYAN SAHU | D12: D | H12: =SUM(E12:F12) -> 0 | I12: 4 | J12: =IF(F12<=17,"0",IF(H12<=39,"0",IF(H12<=49,"4",IF(H12<=54,"5",IF(H12<=59,"6",IF(H12<=69,"7",IF(H12<=79,"8",IF(H12<=89,"9","10")))))))) -> 0 | K12: =IF(F12<=17,"F",IF(H12<=39,"F",IF(H12<=49,"P",IF(H12<=54,"C",IF(H12<=59,"B",IF(H12<=69,"B+",IF(H12<=79,"A",IF(H12<=89,"A+","O")))))))) -> F | L12: =I12*J12 -> 0 | Q12: =SUM(N12:O12) -> 0 | R12: 4 | S12: =IF(O12<=17,"0",IF(Q12<=39,"4",IF(Q12<=49,"4",IF(Q12<=54,"5",IF(Q12<=59,"6",IF(Q12<=69,"7",IF(Q12<=79,"8",IF(Q12<=89,"9","10")))))))) -> 0 | T12: =IF(O12<=17,"F",IF(Q12<=39,"F",IF(Q12<=49,"P",IF(Q12<=54,"C",IF(Q12<=59,"B",IF(Q12<=69,"B+",IF(Q12<=79,"A",IF(Q12<=89,"A+","O")))))))) -> F | U12: =R12*S12 -> 0 | Z12: =SUM(W12:X12) -> 0 | AA12: 3 | AB12: =IF(X12<=17,"0",IF(Z12<=39,"0",IF(Z12<=49,"4",IF(Z12<=54,"5",IF(Z12<=59,"6",IF(Z12<=69,"7",IF(Z12<=79,"8",IF(Z12<=89,"9","10")))))))) -> 0 | AC12: =IF(X12<=17,"F",IF(Z12<=39,"F",IF(Z12<=49,"P",IF(Z12<=54,"C",IF(Z12<=59,"B",IF(Z12<=69,"B+",IF(Z12<=79,"A",IF(Z12<=89,"A+","O")))))))) -> F | AD12: =AA12*AB12 -> 0 | AI12: =SUM(AF12:AG12) -> 0 | AJ12: 3 | AK12: =IF(AG12<=17,"0",IF(AI12<=39,"0",IF(AI12<=49,"4",IF(AI12<=54,"5",IF(AI12<=59,"6",IF(AI12<=69,"7",IF(AI12<=79,"8",IF(AI12<=89,"9","10")))))))) -> 0 | AL12: =IF(AG12<=17,"F",IF(AI12<=39,"F",IF(AI12<=49,"P",IF(AI12<=54,"C",IF(AI12<=59,"B",IF(AI12<=69,"B+",IF(AI12<=79,"A",IF(AI12<=89,"A+","O")))))))) -> F | AM12: =AJ12*AK12 -> 0 | AR12: =(AO12+AP12) -> 0 | AS12: 3 | AT12: =IF(AP12<=17,"0",IF(AR12<=39,"0",IF(AR12<=49,"4",IF(AR12<=54,"5",IF(AR12<=59,"6",IF(AR12<=69,"7",IF(AR12<=79,"8",IF(AR12<=89,"9","10")))))))) -> 0 | AU12: =IF(AP12<=17,"F",IF(AR12<=39,"F",IF(AR12<=49,"P",IF(AR12<=54,"C",IF(AR12<=59,"B",IF(AR12<=69,"B+",IF(AR12<=79,"A",IF(AR12<=89,"A+","O")))))))) -> F | AV12: =AS12*AT12 -> 0 | BA12: =(AX12+AY12) -> 0 | BB12: 1 | BC12: =IF(AY12<=17,"0",IF(BA12<=39,"0",IF(BA12<=49,"4",IF(BA12<=54,"5",IF(BA12<=59,"6",IF(BA12<=69,"7",IF(BA12<=79,"8",IF(BA12<=89,"9","10")))))))) -> 0 | BD12: =IF(AY12<=17,"F",IF(BA12<=39,"F",IF(BA12<=49,"P",IF(BA12<=54,"C",IF(BA12<=59,"B",IF(BA12<=69,"B+",IF(BA12<=79,"A",IF(BA12<=89,"A+","O")))))))) -> F | BE12: =BB12*BC12 -> 0 | BF12: Samskrutika Kannada | BJ12: =(BG12+BH12) -> 0 | BK12: 1 | BL12: =IF(BH12<=17,"0",IF(BJ12<=39,"0",IF(BJ12<=49,"4",IF(BJ12<=54,"5",IF(BJ12<=59,"6",IF(BJ12<=69,"7",IF(BJ12<=79,"8",IF(BJ12<=89,"9","10")))))))) -> 0 | BM12: =IF(BH12<=17,"F",IF(BJ12<=39,"F",IF(BJ12<=49,"P",IF(BJ12<=54,"C",IF(BJ12<=59,"B",IF(BJ12<=69,"B+",IF(BJ12<=79,"A",IF(BJ12<=89,"A+","O")))))))) -> F | BN12: =BK12*BL12 -> 0 | BS12: =(BP12+BQ12) -> 0 | BT12: 1 | BU12: =IF(BQ12<=17,"0",IF(BS12<=39,"0",IF(BS12<=49,"4",IF(BS12<=54,"5",IF(BS12<=59,"6",IF(BS12<=69,"7",IF(BS12<=79,"8",IF(BS12<=89,"9","10")))))))) -> 0 | BV12: =IF(BQ12<=17,"F",IF(BS12<=39,"F",IF(BS12<=49,"P",IF(BS12<=54,"C",IF(BS12<=59,"B",IF(BS12<=69,"B+",IF(BS12<=79,"A",IF(BS12<=89,"A+","O")))))))) -> F | BW12: =BT12*BU12 -> 0 | BZ12: =L12+U12+AD12+AM12+AV12+BE12+BN12+BW12 -> 0 | CA12: =BZ12/20 -> 0 | CB12: =IF(CA12<4,"F",IF(BV12="F","F",IF(BM12="F","F",IF(BD12="F","F",IF(AU12="F","F",IF(AL12="F","F",IF(AC12="F","F",IF(T12="F","F",IF(K12="F","F",IF(CA12<=5,"C",IF(CA12<6,"B",IF(CA12<7,"B+",IF(CA12<8,"A",IF(CA12<=9,"A+","O")))))))))))))) -> F | CC12: =CA12*9.5 -> 0 | CE12: =SUM(BS12,BJ12,BA12,AR12,AI12,Z12,Q12,H12) -> 0 | CF12: =(CE12/800)*100 -> 0 | CI12: =IF(CA12<=4,"F",IF(CA12<=6,"PASS",IF(CA12<=6.5,"SC",IF(CA12<=7.5,"FC",IF(CA12<="10","FCD"))))) -> F
A13: =A12+1 -> 6 | B13: 1BI23CD006 | C13: ASHWINI KULKARNI | D13: D | H13: =SUM(E13:F13) -> 0 | I13: 4 | J13: =IF(F13<=17,"0",IF(H13<=39,"0",IF(H13<=49,"4",IF(H13<=54,"5",IF(H13<=59,"6",IF(H13<=69,"7",IF(H13<=79,"8",IF(H13<=89,"9","10")))))))) -> 0 | K13: =IF(F13<=17,"F",IF(H13<=39,"F",IF(H13<=49,"P",IF(H13<=54,"C",IF(H13<=59,"B",IF(H13<=69,"B+",IF(H13<=79,"A",IF(H13<=89,"A+","O")))))))) -> F | L13: =I13*J13 -> 0 | Q13: =SUM(N13:O13) -> 0 | R13: 4 | S13: =IF(O13<=17,"0",IF(Q13<=39,"4",IF(Q13<=49,"4",IF(Q13<=54,"5",IF(Q13<=59,"6",IF(Q13<=69,"7",IF(Q13<=79,"8",IF(Q13<=89,"9","10")))))))) -> 0 | T13: =IF(O13<=17,"F",IF(Q13<=39,"F",IF(Q13<=49,"P",IF(Q13<=54,"C",IF(Q13<=59,"B",IF(Q13<=69,"B+",IF(Q13<=79,"A",IF(Q13<=89,"A+","O")))))))) -> F | U13: =R13*S13 -> 0 | Z13: =SUM(W13:X13) -> 0 | AA13: 3 | AB13: =IF(X13<=17,"0",IF(Z13<=39,"0",IF(Z13<=49,"4",IF(Z13<=54,"5",IF(Z13<=59,"6",IF(Z13<=69,"7",IF(Z13<=79,"8",IF(Z13<=89,"9","10")))))))) -> 0 | AC13: =IF(X13<=17,"F",IF(Z13<=39,"F",IF(Z13<=49,"P",IF(Z13<=54,"C",IF(Z13<=59,"B",IF(Z13<=69,"B+",IF(Z13<=79,"A",IF(Z13<=89,"A+","O")))))))) -> F | AD13: =AA13*AB13 -> 0 | AI13: =SUM(AF13:AG13) -> 0 | AJ13: 3 | AK13: =IF(AG13<=17,"0",IF(AI13<=39,"0",IF(AI13<=49,"4",IF(AI13<=54,"5",IF(AI13<=59,"6",IF(AI13<=69,"7",IF(AI13<=79,"8",IF(AI13<=89,"9","10")))))))) -> 0 | AL13: =IF(AG13<=17,"F",IF(AI13<=39,"F",IF(AI13<=49,"P",IF(AI13<=54,"C",IF(AI13<=59,"B",IF(AI13<=69,"B+",IF(AI13<=79,"A",IF(AI13<=89,"A+","O")))))))) -> F | AM13: =AJ13*AK13 -> 0 | AR13: =(AO13+AP13) -> 0 | AS13: 3 | AT13: =IF(AP13<=17,"0",IF(AR13<=39,"0",IF(AR13<=49,"4",IF(AR13<=54,"5",IF(AR13<=59,"6",IF(AR13<=69,"7",IF(AR13<=79,"8",IF(AR13<=89,"9","10")))))))) -> 0 | AU13: =IF(AP13<=17,"F",IF(AR13<=39,"F",IF(AR13<=49,"P",IF(AR13<=54,"C",IF(AR13<=59,"B",IF(AR13<=69,"B+",IF(AR13<=79,"A",IF(AR13<=89,"A+","O")))))))) -> F | AV13: =AS13*AT13 -> 0 | BA13: =(AX13+AY13) -> 0 | BB13: 1 | BC13: =IF(AY13<=17,"0",IF(BA13<=39,"0",IF(BA13<=49,"4",IF(BA13<=54,"5",IF(BA13<=59,"6",IF(BA13<=69,"7",IF(BA13<=79,"8",IF(BA13<=89,"9","10")))))))) -> 0 | BD13: =IF(AY13<=17,"F",IF(BA13<=39,"F",IF(BA13<=49,"P",IF(BA13<=54,"C",IF(BA13<=59,"B",IF(BA13<=69,"B+",IF(BA13<=79,"A",IF(BA13<=89,"A+","O")))))))) -> F | BE13: =BB13*BC13 -> 0 | BF13: Samskrutika Kannada | BJ13: =(BG13+BH13) -> 0 | BK13: 1 | BL13: =IF(BH13<=17,"0",IF(BJ13<=39,"0",IF(BJ13<=49,"4",IF(BJ13<=54,"5",IF(BJ13<=59,"6",IF(BJ13<=69,"7",IF(BJ13<=79,"8",IF(BJ13<=89,"9","10")))))))) -> 0 | BM13: =IF(BH13<=17,"F",IF(BJ13<=39,"F",IF(BJ13<=49,"P",IF(BJ13<=54,"C",IF(BJ13<=59,"B",IF(BJ13<=69,"B+",IF(BJ13<=79,"A",IF(BJ13<=89,"A+","O")))))))) -> F | BN13: =BK13*BL13 -> 0 | BS13: =(BP13+BQ13) -> 0 | BT13: 1 | BU13: =IF(BQ13<=17,"0",IF(BS13<=39,"0",IF(BS13<=49,"4",IF(BS13<=54,"5",IF(BS13<=59,"6",IF(BS13<=69,"7",IF(BS13<=79,"8",IF(BS13<=89,"9","10")))))))) -> 0 | BV13: =IF(BQ13<=17,"F",IF(BS13<=39,"F",IF(BS13<=49,"P",IF(BS13<=54,"C",IF(BS13<=59,"B",IF(BS13<=69,"B+",IF(BS13<=79,"A",IF(BS13<=89,"A+","O")))))))) -> F | BW13: =BT13*BU13 -> 0 | BZ13: =L13+U13+AD13+AM13+AV13+BE13+BN13+BW13 -> 0 | CA13: =BZ13/20 -> 0 | CB13: =IF(CA13<4,"F",IF(BV13="F","F",IF(BM13="F","F",IF(BD13="F","F",IF(AU13="F","F",IF(AL13="F","F",IF(AC13="F","F",IF(T13="F","F",IF(K13="F","F",IF(CA13<=5,"C",IF(CA13<6,"B",IF(CA13<7,"B+",IF(CA13<8,"A",IF(CA13<=9,"A+","O")))))))))))))) -> F | CC13: =CA13*9.5 -> 0 | CE13: =SUM(BS13,BJ13,BA13,AR13,AI13,Z13,Q13,H13) -> 0 | CF13: =(CE13/800)*100 -> 0 | CI13: =IF(CA13<=4,"F",IF(CA13<=6,"PASS",IF(CA13<=6.5,"SC",IF(CA13<=7.5,"FC",IF(CA13<="10","FCD"))))) -> F
A14: =A13+1 -> 7 | B14: 1BI23CD007 | C14: AYUSH KUMAR | D14: D | H14: =SUM(E14:F14) -> 0 | I14: 4 | J14: =IF(F14<=17,"0",IF(H14<=39,"0",IF(H14<=49,"4",IF(H14<=54,"5",IF(H14<=59,"6",IF(H14<=69,"7",IF(H14<=79,"8",IF(H14<=89,"9","10")))))))) -> 0 | K14: =IF(F14<=17,"F",IF(H14<=39,"F",IF(H14<=49,"P",IF(H14<=54,"C",IF(H14<=59,"B",IF(H14<=69,"B+",IF(H14<=79,"A",IF(H14<=89,"A+","O")))))))) -> F | L14: =I14*J14 -> 0 | Q14: =SUM(N14:O14) -> 0 | R14: 4 | S14: =IF(O14<=17,"0",IF(Q14<=39,"4",IF(Q14<=49,"4",IF(Q14<=54,"5",IF(Q14<=59,"6",IF(Q14<=69,"7",IF(Q14<=79,"8",IF(Q14<=89,"9","10")))))))) -> 0 | T14: =IF(O14<=17,"F",IF(Q14<=39,"F",IF(Q14<=49,"P",IF(Q14<=54,"C",IF(Q14<=59,"B",IF(Q14<=69,"B+",IF(Q14<=79,"A",IF(Q14<=89,"A+","O")))))))) -> F | U14: =R14*S14 -> 0 | Z14: =SUM(W14:X14) -> 0 | AA14: 3 | AB14: =IF(X14<=17,"0",IF(Z14<=39,"0",IF(Z14<=49,"4",IF(Z14<=54,"5",IF(Z14<=59,"6",IF(Z14<=69,"7",IF(Z14<=79,"8",IF(Z14<=89,"9","10")))))))) -> 0 | AC14: =IF(X14<=17,"F",IF(Z14<=39,"F",IF(Z14<=49,"P",IF(Z14<=54,"C",IF(Z14<=59,"B",IF(Z14<=69,"B+",IF(Z14<=79,"A",IF(Z14<=89,"A+","O")))))))) -> F | AD14: =AA14*AB14 -> 0 | AI14: =SUM(AF14:AG14) -> 0 | AJ14: 3 | AK14: =IF(AG14<=17,"0",IF(AI14<=39,"0",IF(AI14<=49,"4",IF(AI14<=54,"5",IF(AI14<=59,"6",IF(AI14<=69,"7",IF(AI14<=79,"8",IF(AI14<=89,"9","10")))))))) -> 0 | AL14: =IF(AG14<=17,"F",IF(AI14<=39,"F",IF(AI14<=49,"P",IF(AI14<=54,"C",IF(AI14<=59,"B",IF(AI14<=69,"B+",IF(AI14<=79,"A",IF(AI14<=89,"A+","O")))))))) -> F | AM14: =AJ14*AK14 -> 0 | AR14: =(AO14+AP14) -> 0 | AS14: 3 | AT14: =IF(AP14<=17,"0",IF(AR14<=39,"0",IF(AR14<=49,"4",IF(AR14<=54,"5",IF(AR14<=59,"6",IF(AR14<=69,"7",IF(AR14<=79,"8",IF(AR14<=89,"9","10")))))))) -> 0 | AU14: =IF(AP14<=17,"F",IF(AR14<=39,"F",IF(AR14<=49,"P",IF(AR14<=54,"C",IF(AR14<=59,"B",IF(AR14<=69,"B+",IF(AR14<=79,"A",IF(AR14<=89,"A+","O")))))))) -> F | AV14: =AS14*AT14 -> 0 | BA14: =(AX14+AY14) -> 0 | BB14: 1 | BC14: =IF(AY14<=17,"0",IF(BA14<=39,"0",IF(BA14<=49,"4",IF(BA14<=54,"5",IF(BA14<=59,"6",IF(BA14<=69,"7",IF(BA14<=79,"8",IF(BA14<=89,"9","10")))))))) -> 0 | BD14: =IF(AY14<=17,"F",IF(BA14<=39,"F",IF(BA14<=49,"P",IF(BA14<=54,"C",IF(BA14<=59,"B",IF(BA14<=69,"B+",IF(BA14<=79,"A",IF(BA14<=89,"A+","O")))))))) -> F | BE14: =BB14*BC14 -> 0 | BF14: Samskrutika Kannada | BJ14: =(BG14+BH14) -> 0 | BK14: 1 | BL14: =IF(BH14<=17,"0",IF(BJ14<=39,"0",IF(BJ14<=49,"4",IF(BJ14<=54,"5",IF(BJ14<=59,"6",IF(BJ14<=69,"7",IF(BJ14<=79,"8",IF(BJ14<=89,"9","10")))))))) -> 0 | BM14: =IF(BH14<=17,"F",IF(BJ14<=39,"F",IF(BJ14<=49,"P",IF(BJ14<=54,"C",IF(BJ14<=59,"B",IF(BJ14<=69,"B+",IF(BJ14<=79,"A",IF(BJ14<=89,"A+","O")))))))) -> F | BN14: =BK14*BL14 -> 0 | BS14: =(BP14+BQ14) -> 0 | BT14: 1 | BU14: =IF(BQ14<=17,"0",IF(BS14<=39,"0",IF(BS14<=49,"4",IF(BS14<=54,"5",IF(BS14<=59,"6",IF(BS14<=69,"7",IF(BS14<=79,"8",IF(BS14<=89,"9","10")))))))) -> 0 | BV14: =IF(BQ14<=17,"F",IF(BS14<=39,"F",IF(BS14<=49,"P",IF(BS14<=54,"C",IF(BS14<=59,"B",IF(BS14<=69,"B+",IF(BS14<=79,"A",IF(BS14<=89,"A+","O")))))))) -> F | BW14: =BT14*BU14 -> 0 | BZ14: =L14+U14+AD14+AM14+AV14+BE14+BN14+BW14 -> 0 | CA14: =BZ14/20 -> 0 | CB14: =IF(CA14<4,"F",IF(BV14="F","F",IF(BM14="F","F",IF(BD14="F","F",IF(AU14="F","F",IF(AL14="F","F",IF(AC14="F","F",IF(T14="F","F",IF(K14="F","F",IF(CA14<=5,"C",IF(CA14<6,"B",IF(CA14<7,"B+",IF(CA14<8,"A",IF(CA14<=9,"A+","O")))))))))))))) -> F | CC14: =CA14*9.5 -> 0 | CE14: =SUM(BS14,BJ14,BA14,AR14,AI14,Z14,Q14,H14) -> 0 | CF14: =(CE14/800)*100 -> 0 | CI14: =IF(CA14<=4,"F",IF(CA14<=6,"PASS",IF(CA14<=6.5,"SC",IF(CA14<=7.5,"FC",IF(CA14<="10","FCD"))))) -> F
A15: =A14+1 -> 8 | B15: 1BI23CD008 | C15: AYUSH KUMAR BHADANI | D15: D | H15: =SUM(E15:F15) -> 0 | I15: 4 | J15: =IF(F15<=17,"0",IF(H15<=39,"0",IF(H15<=49,"4",IF(H15<=54,"5",IF(H15<=59,"6",IF(H15<=69,"7",IF(H15<=79,"8",IF(H15<=89,"9","10")))))))) -> 0 | K15: =IF(F15<=17,"F",IF(H15<=39,"F",IF(H15<=49,"P",IF(H15<=54,"C",IF(H15<=59,"B",IF(H15<=69,"B+",IF(H15<=79,"A",IF(H15<=89,"A+","O")))))))) -> F | L15: =I15*J15 -> 0 | Q15: =SUM(N15:O15) -> 0 | R15: 4 | S15: =IF(O15<=17,"0",IF(Q15<=39,"4",IF(Q15<=49,"4",IF(Q15<=54,"5",IF(Q15<=59,"6",IF(Q15<=69,"7",IF(Q15<=79,"8",IF(Q15<=89,"9","10")))))))) -> 0 | T15: =IF(O15<=17,"F",IF(Q15<=39,"F",IF(Q15<=49,"P",IF(Q15<=54,"C",IF(Q15<=59,"B",IF(Q15<=69,"B+",IF(Q15<=79,"A",IF(Q15<=89,"A+","O")))))))) -> F | U15: =R15*S15 -> 0 | Z15: =SUM(W15:X15) -> 0 | AA15: 3 | AB15: =IF(X15<=17,"0",IF(Z15<=39,"0",IF(Z15<=49,"4",IF(Z15<=54,"5",IF(Z15<=59,"6",IF(Z15<=69,"7",IF(Z15<=79,"8",IF(Z15<=89,"9","10")))))))) -> 0 | AC15: =IF(X15<=17,"F",IF(Z15<=39,"F",IF(Z15<=49,"P",IF(Z15<=54,"C",IF(Z15<=59,"B",IF(Z15<=69,"B+",IF(Z15<=79,"A",IF(Z15<=89,"A+","O")))))))) -> F | AD15: =AA15*AB15 -> 0 | AI15: =SUM(AF15:AG15) -> 0 | AJ15: 3 | AK15: =IF(AG15<=17,"0",IF(AI15<=39,"0",IF(AI15<=49,"4",IF(AI15<=54,"5",IF(AI15<=59,"6",IF(AI15<=69,"7",IF(AI15<=79,"8",IF(AI15<=89,"9","10")))))))) -> 0 | AL15: =IF(AG15<=17,"F",IF(AI15<=39,"F",IF(AI15<=49,"P",IF(AI15<=54,"C",IF(AI15<=59,"B",IF(AI15<=69,"B+",IF(AI15<=79,"A",IF(AI15<=89,"A+","O")))))))) -> F | AM15: =AJ15*AK15 -> 0 | AR15: =(AO15+AP15) -> 0 | AS15: 3 | AT15: =IF(AP15<=17,"0",IF(AR15<=39,"0",IF(AR15<=49,"4",IF(AR15<=54,"5",IF(AR15<=59,"6",IF(AR15<=69,"7",IF(AR15<=79,"8",IF(AR15<=89,"9","10")))))))) -> 0 | AU15: =IF(AP15<=17,"F",IF(AR15<=39,"F",IF(AR15<=49,"P",IF(AR15<=54,"C",IF(AR15<=59,"B",IF(AR15<=69,"B+",IF(AR15<=79,"A",IF(AR15<=89,"A+","O")))))))) -> F | AV15: =AS15*AT15 -> 0 | BA15: =(AX15+AY15) -> 0 | BB15: 1 | BC15: =IF(AY15<=17,"0",IF(BA15<=39,"0",IF(BA15<=49,"4",IF(BA15<=54,"5",IF(BA15<=59,"6",IF(BA15<=69,"7",IF(BA15<=79,"8",IF(BA15<=89,"9","10")))))))) -> 0 | BD15: =IF(AY15<=17,"F",IF(BA15<=39,"F",IF(BA15<=49,"P",IF(BA15<=54,"C",IF(BA15<=59,"B",IF(BA15<=69,"B+",IF(BA15<=79,"A",IF(BA15<=89,"A+","O")))))))) -> F | BE15: =BB15*BC15 -> 0 | BF15: Samskrutika Kannada | BJ15: =(BG15+BH15) -> 0 | BK15: 1 | BL15: =IF(BH15<=17,"0",IF(BJ15<=39,"0",IF(BJ15<=49,"4",IF(BJ15<=54,"5",IF(BJ15<=59,"6",IF(BJ15<=69,"7",IF(BJ15<=79,"8",IF(BJ15<=89,"9","10")))))))) -> 0 | BM15: =IF(BH15<=17,"F",IF(BJ15<=39,"F",IF(BJ15<=49,"P",IF(BJ15<=54,"C",IF(BJ15<=59,"B",IF(BJ15<=69,"B+",IF(BJ15<=79,"A",IF(BJ15<=89,"A+","O")))))))) -> F | BN15: =BK15*BL15 -> 0 | BS15: =(BP15+BQ15) -> 0 | BT15: 1 | BU15: =IF(BQ15<=17,"0",IF(BS15<=39,"0",IF(BS15<=49,"4",IF(BS15<=54,"5",IF(BS15<=59,"6",IF(BS15<=69,"7",IF(BS15<=79,"8",IF(BS15<=89,"9","10")))))))) -> 0 | BV15: =IF(BQ15<=17,"F",IF(BS15<=39,"F",IF(BS15<=49,"P",IF(BS15<=54,"C",IF(BS15<=59,"B",IF(BS15<=69,"B+",IF(BS15<=79,"A",IF(BS15<=89,"A+","O")))))))) -> F | BW15: =BT15*BU15 -> 0 | BZ15: =L15+U15+AD15+AM15+AV15+BE15+BN15+BW15 -> 0 | CA15: =BZ15/20 -> 0 | CB15: =IF(CA15<4,"F",IF(BV15="F","F",IF(BM15="F","F",IF(BD15="F","F",IF(AU15="F","F",IF(AL15="F","F",IF(AC15="F","F",IF(T15="F","F",IF(K15="F","F",IF(CA15<=5,"C",IF(CA15<6,"B",IF(CA15<7,"B+",IF(CA15<8,"A",IF(CA15<=9,"A+","O")))))))))))))) -> F | CC15: =CA15*9.5 -> 0 | CE15: =SUM(BS15,BJ15,BA15,AR15,AI15,Z15,Q15,H15) -> 0 | CF15: =(CE15/800)*100 -> 0 | CI15: =IF(CA15<=4,"F",IF(CA15<=6,"PASS",IF(CA15<=6.5,"SC",IF(CA15<=7.5,"FC",IF(CA15<="10","FCD"))))) -> F
A16: =A15+1 -> 9 | B16: 1BI23CD009 | C16: AYUSH RAJ | D16: D | H16: =SUM(E16:F16) -> 0 | I16: 4 | J16: =IF(F16<=17,"0",IF(H16<=39,"0",IF(H16<=49,"4",IF(H16<=54,"5",IF(H16<=59,"6",IF(H16<=69,"7",IF(H16<=79,"8",IF(H16<=89,"9","10")))))))) -> 0 | K16: =IF(F16<=17,"F",IF(H16<=39,"F",IF(H16<=49,"P",IF(H16<=54,"C",IF(H16<=59,"B",IF(H16<=69,"B+",IF(H16<=79,"A",IF(H16<=89,"A+","O")))))))) -> F | L16: =I16*J16 -> 0 | Q16: =SUM(N16:O16) -> 0 | R16: 4 | S16: =IF(O16<=17,"0",IF(Q16<=39,"4",IF(Q16<=49,"4",IF(Q16<=54,"5",IF(Q16<=59,"6",IF(Q16<=69,"7",IF(Q16<=79,"8",IF(Q16<=89,"9","10")))))))) -> 0 | T16: =IF(O16<=17,"F",IF(Q16<=39,"F",IF(Q16<=49,"P",IF(Q16<=54,"C",IF(Q16<=59,"B",IF(Q16<=69,"B+",IF(Q16<=79,"A",IF(Q16<=89,"A+","O")))))))) -> F | U16: =R16*S16 -> 0 | Z16: =SUM(W16:X16) -> 0 | AA16: 3 | AB16: =IF(X16<=17,"0",IF(Z16<=39,"0",IF(Z16<=49,"4",IF(Z16<=54,"5",IF(Z16<=59,"6",IF(Z16<=69,"7",IF(Z16<=79,"8",IF(Z16<=89,"9","10")))))))) -> 0 | AC16: =IF(X16<=17,"F",IF(Z16<=39,"F",IF(Z16<=49,"P",IF(Z16<=54,"C",IF(Z16<=59,"B",IF(Z16<=69,"B+",IF(Z16<=79,"A",IF(Z16<=89,"A+","O")))))))) -> F | AD16: =AA16*AB16 -> 0 | AI16: =SUM(AF16:AG16) -> 0 | AJ16: 3 | AK16: =IF(AG16<=17,"0",IF(AI16<=39,"0",IF(AI16<=49,"4",IF(AI16<=54,"5",IF(AI16<=59,"6",IF(AI16<=69,"7",IF(AI16<=79,"8",IF(AI16<=89,"9","10")))))))) -> 0 | AL16: =IF(AG16<=17,"F",IF(AI16<=39,"F",IF(AI16<=49,"P",IF(AI16<=54,"C",IF(AI16<=59,"B",IF(AI16<=69,"B+",IF(AI16<=79,"A",IF(AI16<=89,"A+","O")))))))) -> F | AM16: =AJ16*AK16 -> 0 | AR16: =(AO16+AP16) -> 0 | AS16: 3 | AT16: =IF(AP16<=17,"0",IF(AR16<=39,"0",IF(AR16<=49,"4",IF(AR16<=54,"5",IF(AR16<=59,"6",IF(AR16<=69,"7",IF(AR16<=79,"8",IF(AR16<=89,"9","10")))))))) -> 0 | AU16: =IF(AP16<=17,"F",IF(AR16<=39,"F",IF(AR16<=49,"P",IF(AR16<=54,"C",IF(AR16<=59,"B",IF(AR16<=69,"B+",IF(AR16<=79,"A",IF(AR16<=89,"A+","O")))))))) -> F | AV16: =AS16*AT16 -> 0 | BA16: =(AX16+AY16) -> 0 | BB16: 1 | BC16: =IF(AY16<=17,"0",IF(BA16<=39,"0",IF(BA16<=49,"4",IF(BA16<=54,"5",IF(BA16<=59,"6",IF(BA16<=69,"7",IF(BA16<=79,"8",IF(BA16<=89,"9","10")))))))) -> 0 | BD16: =IF(AY16<=17,"F",IF(BA16<=39,"F",IF(BA16<=49,"P",IF(BA16<=54,"C",IF(BA16<=59,"B",IF(BA16<=69,"B+",IF(BA16<=79,"A",IF(BA16<=89,"A+","O")))))))) -> F | BE16: =BB16*BC16 -> 0 | BF16: Samskrutika Kannada | BJ16: =(BG16+BH16) -> 0 | BK16: 1 | BL16: =IF(BH16<=17,"0",IF(BJ16<=39,"0",IF(BJ16<=49,"4",IF(BJ16<=54,"5",IF(BJ16<=59,"6",IF(BJ16<=69,"7",IF(BJ16<=79,"8",IF(BJ16<=89,"9","10")))))))) -> 0 | BM16: =IF(BH16<=17,"F",IF(BJ16<=39,"F",IF(BJ16<=49,"P",IF(BJ16<=54,"C",IF(BJ16<=59,"B",IF(BJ16<=69,"B+",IF(BJ16<=79,"A",IF(BJ16<=89,"A+","O")))))))) -> F | BN16: =BK16*BL16 -> 0 | BS16: =(BP16+BQ16) -> 0 | BT16: 1 | BU16: =IF(BQ16<=17,"0",IF(BS16<=39,"0",IF(BS16<=49,"4",IF(BS16<=54,"5",IF(BS16<=59,"6",IF(BS16<=69,"7",IF(BS16<=79,"8",IF(BS16<=89,"9","10")))))))) -> 0 | BV16: =IF(BQ16<=17,"F",IF(BS16<=39,"F",IF(BS16<=49,"P",IF(BS16<=54,"C",IF(BS16<=59,"B",IF(BS16<=69,"B+",IF(BS16<=79,"A",IF(BS16<=89,"A+","O")))))))) -> F | BW16: =BT16*BU16 -> 0 | BZ16: =L16+U16+AD16+AM16+AV16+BE16+BN16+BW16 -> 0 | CA16: =BZ16/20 -> 0 | CB16: =IF(CA16<4,"F",IF(BV16="F","F",IF(BM16="F","F",IF(BD16="F","F",IF(AU16="F","F",IF(AL16="F","F",IF(AC16="F","F",IF(T16="F","F",IF(K16="F","F",IF(CA16<=5,"C",IF(CA16<6,"B",IF(CA16<7,"B+",IF(CA16<8,"A",IF(CA16<=9,"A+","O")))))))))))))) -> F | CC16: =CA16*9.5 -> 0 | CE16: =SUM(BS16,BJ16,BA16,AR16,AI16,Z16,Q16,H16) -> 0 | CF16: =(CE16/800)*100 -> 0 | CI16: =IF(CA16<=4,"F",IF(CA16<=6,"PASS",IF(CA16<=6.5,"SC",IF(CA16<=7.5,"FC",IF(CA16<="10","FCD"))))) -> F
A17: =A16+1 -> 10 | B17: 1BI23CD010 | C17: B ANKITH KUMAR | D17: D | H17: =SUM(E17:F17) -> 0 | I17: 4 | J17: =IF(F17<=17,"0",IF(H17<=39,"0",IF(H17<=49,"4",IF(H17<=54,"5",IF(H17<=59,"6",IF(H17<=69,"7",IF(H17<=79,"8",IF(H17<=89,"9","10")))))))) -> 0 | K17: =IF(F17<=17,"F",IF(H17<=39,"F",IF(H17<=49,"P",IF(H17<=54,"C",IF(H17<=59,"B",IF(H17<=69,"B+",IF(H17<=79,"A",IF(H17<=89,"A+","O")))))))) -> F | L17: =I17*J17 -> 0 | Q17: =SUM(N17:O17) -> 0 | R17: 4 | S17: =IF(O17<=17,"0",IF(Q17<=39,"4",IF(Q17<=49,"4",IF(Q17<=54,"5",IF(Q17<=59,"6",IF(Q17<=69,"7",IF(Q17<=79,"8",IF(Q17<=89,"9","10")))))))) -> 0 | T17: =IF(O17<=17,"F",IF(Q17<=39,"F",IF(Q17<=49,"P",IF(Q17<=54,"C",IF(Q17<=59,"B",IF(Q17<=69,"B+",IF(Q17<=79,"A",IF(Q17<=89,"A+","O")))))))) -> F | U17: =R17*S17 -> 0 | Z17: =SUM(W17:X17) -> 0 | AA17: 3 | AB17: =IF(X17<=17,"0",IF(Z17<=39,"0",IF(Z17<=49,"4",IF(Z17<=54,"5",IF(Z17<=59,"6",IF(Z17<=69,"7",IF(Z17<=79,"8",IF(Z17<=89,"9","10")))))))) -> 0 | AC17: =IF(X17<=17,"F",IF(Z17<=39,"F",IF(Z17<=49,"P",IF(Z17<=54,"C",IF(Z17<=59,"B",IF(Z17<=69,"B+",IF(Z17<=79,"A",IF(Z17<=89,"A+","O")))))))) -> F | AD17: =AA17*AB17 -> 0 | AI17: =SUM(AF17:AG17) -> 0 | AJ17: 3 | AK17: =IF(AG17<=17,"0",IF(AI17<=39,"0",IF(AI17<=49,"4",IF(AI17<=54,"5",IF(AI17<=59,"6",IF(AI17<=69,"7",IF(AI17<=79,"8",IF(AI17<=89,"9","10")))))))) -> 0 | AL17: =IF(AG17<=17,"F",IF(AI17<=39,"F",IF(AI17<=49,"P",IF(AI17<=54,"C",IF(AI17<=59,"B",IF(AI17<=69,"B+",IF(AI17<=79,"A",IF(AI17<=89,"A+","O")))))))) -> F | AM17: =AJ17*AK17 -> 0 | AR17: =(AO17+AP17) -> 0 | AS17: 3 | AT17: =IF(AP17<=17,"0",IF(AR17<=39,"0",IF(AR17<=49,"4",IF(AR17<=54,"5",IF(AR17<=59,"6",IF(AR17<=69,"7",IF(AR17<=79,"8",IF(AR17<=89,"9","10")))))))) -> 0 | AU17: =IF(AP17<=17,"F",IF(AR17<=39,"F",IF(AR17<=49,"P",IF(AR17<=54,"C",IF(AR17<=59,"B",IF(AR17<=69,"B+",IF(AR17<=79,"A",IF(AR17<=89,"A+","O")))))))) -> F | AV17: =AS17*AT17 -> 0 | BA17: =(AX17+AY17) -> 0 | BB17: 1 | BC17: =IF(AY17<=17,"0",IF(BA17<=39,"0",IF(BA17<=49,"4",IF(BA17<=54,"5",IF(BA17<=59,"6",IF(BA17<=69,"7",IF(BA17<=79,"8",IF(BA17<=89,"9","10")))))))) -> 0 | BD17: =IF(AY17<=17,"F",IF(BA17<=39,"F",IF(BA17<=49,"P",IF(BA17<=54,"C",IF(BA17<=59,"B",IF(BA17<=69,"B+",IF(BA17<=79,"A",IF(BA17<=89,"A+","O")))))))) -> F | BE17: =BB17*BC17 -> 0 | BF17: Samskrutika Kannada | BJ17: =(BG17+BH17) -> 0 | BK17: 1 | BL17: =IF(BH17<=17,"0",IF(BJ17<=39,"0",IF(BJ17<=49,"4",IF(BJ17<=54,"5",IF(BJ17<=59,"6",IF(BJ17<=69,"7",IF(BJ17<=79,"8",IF(BJ17<=89,"9","10")))))))) -> 0 | BM17: =IF(BH17<=17,"F",IF(BJ17<=39,"F",IF(BJ17<=49,"P",IF(BJ17<=54,"C",IF(BJ17<=59,"B",IF(BJ17<=69,"B+",IF(BJ17<=79,"A",IF(BJ17<=89,"A+","O")))))))) -> F | BN17: =BK17*BL17 -> 0 | BS17: =(BP17+BQ17) -> 0 | BT17: 1 | BU17: =IF(BQ17<=17,"0",IF(BS17<=39,"0",IF(BS17<=49,"4",IF(BS17<=54,"5",IF(BS17<=59,"6",IF(BS17<=69,"7",IF(BS17<=79,"8",IF(BS17<=89,"9","10")))))))) -> 0 | BV17: =IF(BQ17<=17,"F",IF(BS17<=39,"F",IF(BS17<=49,"P",IF(BS17<=54,"C",IF(BS17<=59,"B",IF(BS17<=69,"B+",IF(BS17<=79,"A",IF(BS17<=89,"A+","O")))))))) -> F | BW17: =BT17*BU17 -> 0 | BZ17: =L17+U17+AD17+AM17+AV17+BE17+BN17+BW17 -> 0 | CA17: =BZ17/20 -> 0 | CB17: =IF(CA17<4,"F",IF(BV17="F","F",IF(BM17="F","F",IF(BD17="F","F",IF(AU17="F","F",IF(AL17="F","F",IF(AC17="F","F",IF(T17="F","F",IF(K17="F","F",IF(CA17<=5,"C",IF(CA17<6,"B",IF(CA17<7,"B+",IF(CA17<8,"A",IF(CA17<=9,"A+","O")))))))))))))) -> F | CC17: =CA17*9.5 -> 0 | CE17: =SUM(BS17,BJ17,BA17,AR17,AI17,Z17,Q17,H17) -> 0 | CF17: =(CE17/800)*100 -> 0 | CI17: =IF(CA17<=4,"F",IF(CA17<=6,"PASS",IF(CA17<=6.5,"SC",IF(CA17<=7.5,"FC",IF(CA17<="10","FCD"))))) -> F
A18: =A17+1 -> 11 | B18: 1BI23CD011 | C18: BASAVARAJ | D18: D | H18: =SUM(E18:F18) -> 0 | I18: 4 | J18: =IF(F18<=17,"0",IF(H18<=39,"0",IF(H18<=49,"4",IF(H18<=54,"5",IF(H18<=59,"6",IF(H18<=69,"7",IF(H18<=79,"8",IF(H18<=89,"9","10")))))))) -> 0 | K18: =IF(F18<=17,"F",IF(H18<=39,"F",IF(H18<=49,"P",IF(H18<=54,"C",IF(H18<=59,"B",IF(H18<=69,"B+",IF(H18<=79,"A",IF(H18<=89,"A+","O")))))))) -> F | L18: =I18*J18 -> 0 | Q18: =SUM(N18:O18) -> 0 | R18: 4 | S18: =IF(O18<=17,"0",IF(Q18<=39,"4",IF(Q18<=49,"4",IF(Q18<=54,"5",IF(Q18<=59,"6",IF(Q18<=69,"7",IF(Q18<=79,"8",IF(Q18<=89,"9","10")))))))) -> 0 | T18: =IF(O18<=17,"F",IF(Q18<=39,"F",IF(Q18<=49,"P",IF(Q18<=54,"C",IF(Q18<=59,"B",IF(Q18<=69,"B+",IF(Q18<=79,"A",IF(Q18<=89,"A+","O")))))))) -> F | U18: =R18*S18 -> 0 | Z18: =SUM(W18:X18) -> 0 | AA18: 3 | AB18: =IF(X18<=17,"0",IF(Z18<=39,"0",IF(Z18<=49,"4",IF(Z18<=54,"5",IF(Z18<=59,"6",IF(Z18<=69,"7",IF(Z18<=79,"8",IF(Z18<=89,"9","10")))))))) -> 0 | AC18: =IF(X18<=17,"F",IF(Z18<=39,"F",IF(Z18<=49,"P",IF(Z18<=54,"C",IF(Z18<=59,"B",IF(Z18<=69,"B+",IF(Z18<=79,"A",IF(Z18<=89,"A+","O")))))))) -> F | AD18: =AA18*AB18 -> 0 | AI18: =SUM(AF18:AG18) -> 0 | AJ18: 3 | AK18: =IF(AG18<=17,"0",IF(AI18<=39,"0",IF(AI18<=49,"4",IF(AI18<=54,"5",IF(AI18<=59,"6",IF(AI18<=69,"7",IF(AI18<=79,"8",IF(AI18<=89,"9","10")))))))) -> 0 | AL18: =IF(AG18<=17,"F",IF(AI18<=39,"F",IF(AI18<=49,"P",IF(AI18<=54,"C",IF(AI18<=59,"B",IF(AI18<=69,"B+",IF(AI18<=79,"A",IF(AI18<=89,"A+","O")))))))) -> F | AM18: =AJ18*AK18 -> 0 | AR18: =(AO18+AP18) -> 0 | AS18: 3 | AT18: =IF(AP18<=17,"0",IF(AR18<=39,"0",IF(AR18<=49,"4",IF(AR18<=54,"5",IF(AR18<=59,"6",IF(AR18<=69,"7",IF(AR18<=79,"8",IF(AR18<=89,"9","10")))))))) -> 0 | AU18: =IF(AP18<=17,"F",IF(AR18<=39,"F",IF(AR18<=49,"P",IF(AR18<=54,"C",IF(AR18<=59,"B",IF(AR18<=69,"B+",IF(AR18<=79,"A",IF(AR18<=89,"A+","O")))))))) -> F | AV18: =AS18*AT18 -> 0 | BA18: =(AX18+AY18) -> 0 | BB18: 1 | BC18: =IF(AY18<=17,"0",IF(BA18<=39,"0",IF(BA18<=49,"4",IF(BA18<=54,"5",IF(BA18<=59,"6",IF(BA18<=69,"7",IF(BA18<=79,"8",IF(BA18<=89,"9","10")))))))) -> 0 | BD18: =IF(AY18<=17,"F",IF(BA18<=39,"F",IF(BA18<=49,"P",IF(BA18<=54,"C",IF(BA18<=59,"B",IF(BA18<=69,"B+",IF(BA18<=79,"A",IF(BA18<=89,"A+","O")))))))) -> F | BE18: =BB18*BC18 -> 0 | BF18: Balake Kannada | BJ18: =(BG18+BH18) -> 0 | BK18: 1 | BL18: =IF(BH18<=17,"0",IF(BJ18<=39,"0",IF(BJ18<=49,"4",IF(BJ18<=54,"5",IF(BJ18<=59,"6",IF(BJ18<=69,"7",IF(BJ18<=79,"8",IF(BJ18<=89,"9","10")))))))) -> 0 | BM18: =IF(BH18<=17,"F",IF(BJ18<=39,"F",IF(BJ18<=49,"P",IF(BJ18<=54,"C",IF(BJ18<=59,"B",IF(BJ18<=69,"B+",IF(BJ18<=79,"A",IF(BJ18<=89,"A+","O")))))))) -> F | BN18: =BK18*BL18 -> 0 | BS18: =(BP18+BQ18) -> 0 | BT18: 1 | BU18: =IF(BQ18<=17,"0",IF(BS18<=39,"0",IF(BS18<=49,"4",IF(BS18<=54,"5",IF(BS18<=59,"6",IF(BS18<=69,"7",IF(BS18<=79,"8",IF(BS18<=89,"9","10")))))))) -> 0 | BV18: =IF(BQ18<=17,"F",IF(BS18<=39,"F",IF(BS18<=49,"P",IF(BS18<=54,"C",IF(BS18<=59,"B",IF(BS18<=69,"B+",IF(BS18<=79,"A",IF(BS18<=89,"A+","O")))))))) -> F | BW18: =BT18*BU18 -> 0 | BZ18: =L18+U18+AD18+AM18+AV18+BE18+BN18+BW18 -> 0 | CA18: =BZ18/20 -> 0 | CB18: =IF(CA18<4,"F",IF(BV18="F","F",IF(BM18="F","F",IF(BD18="F","F",IF(AU18="F","F",IF(AL18="F","F",IF(AC18="F","F",IF(T18="F","F",IF(K18="F","F",IF(CA18<=5,"C",IF(CA18<6,"B",IF(CA18<7,"B+",IF(CA18<8,"A",IF(CA18<=9,"A+","O")))))))))))))) -> F | CC18: =CA18*9.5 -> 0 | CE18: =SUM(BS18,BJ18,BA18,AR18,AI18,Z18,Q18,H18) -> 0 | CF18: =(CE18/800)*100 -> 0 | CI18: =IF(CA18<=4,"F",IF(CA18<=6,"PASS",IF(CA18<=6.5,"SC",IF(CA18<=7.5,"FC",IF(CA18<="10","FCD"))))) -> F
A19: =A18+1 -> 12 | B19: 1BI23CD012 | C19: BINDU SHREE R | D19: D | H19: =SUM(E19:F19) -> 0 | I19: 4 | J19: =IF(F19<=17,"0",IF(H19<=39,"0",IF(H19<=49,"4",IF(H19<=54,"5",IF(H19<=59,"6",IF(H19<=69,"7",IF(H19<=79,"8",IF(H19<=89,"9","10")))))))) -> 0 | K19: =IF(F19<=17,"F",IF(H19<=39,"F",IF(H19<=49,"P",IF(H19<=54,"C",IF(H19<=59,"B",IF(H19<=69,"B+",IF(H19<=79,"A",IF(H19<=89,"A+","O")))))))) -> F | L19: =I19*J19 -> 0 | Q19: =SUM(N19:O19) -> 0 | R19: 4 | S19: =IF(O19<=17,"0",IF(Q19<=39,"4",IF(Q19<=49,"4",IF(Q19<=54,"5",IF(Q19<=59,"6",IF(Q19<=69,"7",IF(Q19<=79,"8",IF(Q19<=89,"9","10")))))))) -> 0 | T19: =IF(O19<=17,"F",IF(Q19<=39,"F",IF(Q19<=49,"P",IF(Q19<=54,"C",IF(Q19<=59,"B",IF(Q19<=69,"B+",IF(Q19<=79,"A",IF(Q19<=89,"A+","O")))))))) -> F | U19: =R19*S19 -> 0 | Z19: =SUM(W19:X19) -> 0 | AA19: 3 | AB19: =IF(X19<=17,"0",IF(Z19<=39,"0",IF(Z19<=49,"4",IF(Z19<=54,"5",IF(Z19<=59,"6",IF(Z19<=69,"7",IF(Z19<=79,"8",IF(Z19<=89,"9","10")))))))) -> 0 | AC19: =IF(X19<=17,"F",IF(Z19<=39,"F",IF(Z19<=49,"P",IF(Z19<=54,"C",IF(Z19<=59,"B",IF(Z19<=69,"B+",IF(Z19<=79,"A",IF(Z19<=89,"A+","O")))))))) -> F | AD19: =AA19*AB19 -> 0 | AI19: =SUM(AF19:AG19) -> 0 | AJ19: 3 | AK19: =IF(AG19<=17,"0",IF(AI19<=39,"0",IF(AI19<=49,"4",IF(AI19<=54,"5",IF(AI19<=59,"6",IF(AI19<=69,"7",IF(AI19<=79,"8",IF(AI19<=89,"9","10")))))))) -> 0 | AL19: =IF(AG19<=17,"F",IF(AI19<=39,"F",IF(AI19<=49,"P",IF(AI19<=54,"C",IF(AI19<=59,"B",IF(AI19<=69,"B+",IF(AI19<=79,"A",IF(AI19<=89,"A+","O")))))))) -> F | AM19: =AJ19*AK19 -> 0 | AR19: =(AO19+AP19) -> 0 | AS19: 3 | AT19: =IF(AP19<=17,"0",IF(AR19<=39,"0",IF(AR19<=49,"4",IF(AR19<=54,"5",IF(AR19<=59,"6",IF(AR19<=69,"7",IF(AR19<=79,"8",IF(AR19<=89,"9","10")))))))) -> 0 | AU19: =IF(AP19<=17,"F",IF(AR19<=39,"F",IF(AR19<=49,"P",IF(AR19<=54,"C",IF(AR19<=59,"B",IF(AR19<=69,"B+",IF(AR19<=79,"A",IF(AR19<=89,"A+","O")))))))) -> F | AV19: =AS19*AT19 -> 0 | BA19: =(AX19+AY19) -> 0 | BB19: 1 | BC19: =IF(AY19<=17,"0",IF(BA19<=39,"0",IF(BA19<=49,"4",IF(BA19<=54,"5",IF(BA19<=59,"6",IF(BA19<=69,"7",IF(BA19<=79,"8",IF(BA19<=89,"9","10")))))))) -> 0 | BD19: =IF(AY19<=17,"F",IF(BA19<=39,"F",IF(BA19<=49,"P",IF(BA19<=54,"C",IF(BA19<=59,"B",IF(BA19<=69,"B+",IF(BA19<=79,"A",IF(BA19<=89,"A+","O")))))))) -> F | BE19: =BB19*BC19 -> 0 | BF19: Samskrutika Kannada | BJ19: =(BG19+BH19) -> 0 | BK19: 1 | BL19: =IF(BH19<=17,"0",IF(BJ19<=39,"0",IF(BJ19<=49,"4",IF(BJ19<=54,"5",IF(BJ19<=59,"6",IF(BJ19<=69,"7",IF(BJ19<=79,"8",IF(BJ19<=89,"9","10")))))))) -> 0 | BM19: =IF(BH19<=17,"F",IF(BJ19<=39,"F",IF(BJ19<=49,"P",IF(BJ19<=54,"C",IF(BJ19<=59,"B",IF(BJ19<=69,"B+",IF(BJ19<=79,"A",IF(BJ19<=89,"A+","O")))))))) -> F | BN19: =BK19*BL19 -> 0 | BS19: =(BP19+BQ19) -> 0 | BT19: 1 | BU19: =IF(BQ19<=17,"0",IF(BS19<=39,"0",IF(BS19<=49,"4",IF(BS19<=54,"5",IF(BS19<=59,"6",IF(BS19<=69,"7",IF(BS19<=79,"8",IF(BS19<=89,"9","10")))))))) -> 0 | BV19: =IF(BQ19<=17,"F",IF(BS19<=39,"F",IF(BS19<=49,"P",IF(BS19<=54,"C",IF(BS19<=59,"B",IF(BS19<=69,"B+",IF(BS19<=79,"A",IF(BS19<=89,"A+","O")))))))) -> F | BW19: =BT19*BU19 -> 0 | BZ19: =L19+U19+AD19+AM19+AV19+BE19+BN19+BW19 -> 0 | CA19: =BZ19/20 -> 0 | CB19: =IF(CA19<4,"F",IF(BV19="F","F",IF(BM19="F","F",IF(BD19="F","F",IF(AU19="F","F",IF(AL19="F","F",IF(AC19="F","F",IF(T19="F","F",IF(K19="F","F",IF(CA19<=5,"C",IF(CA19<6,"B",IF(CA19<7,"B+",IF(CA19<8,"A",IF(CA19<=9,"A+","O")))))))))))))) -> F | CC19: =CA19*9.5 -> 0 | CE19: =SUM(BS19,BJ19,BA19,AR19,AI19,Z19,Q19,H19) -> 0 | CF19: =(CE19/800)*100 -> 0 | CI19: =IF(CA19<=4,"F",IF(CA19<=6,"PASS",IF(CA19<=6.5,"SC",IF(CA19<=7.5,"FC",IF(CA19<="10","FCD"))))) -> F
A20: =A19+1 -> 13 | B20: 1BI23CD013 | C20: CHETHAN S | D20: D | H20: =SUM(E20:F20) -> 0 | I20: 4 | J20: =IF(F20<=17,"0",IF(H20<=39,"0",IF(H20<=49,"4",IF(H20<=54,"5",IF(H20<=59,"6",IF(H20<=69,"7",IF(H20<=79,"8",IF(H20<=89,"9","10")))))))) -> 0 | K20: =IF(F20<=17,"F",IF(H20<=39,"F",IF(H20<=49,"P",IF(H20<=54,"C",IF(H20<=59,"B",IF(H20<=69,"B+",IF(H20<=79,"A",IF(H20<=89,"A+","O")))))))) -> F | L20: =I20*J20 -> 0 | Q20: =SUM(N20:O20) -> 0 | R20: 4 | S20: =IF(O20<=17,"0",IF(Q20<=39,"4",IF(Q20<=49,"4",IF(Q20<=54,"5",IF(Q20<=59,"6",IF(Q20<=69,"7",IF(Q20<=79,"8",IF(Q20<=89,"9","10")))))))) -> 0 | T20: =IF(O20<=17,"F",IF(Q20<=39,"F",IF(Q20<=49,"P",IF(Q20<=54,"C",IF(Q20<=59,"B",IF(Q20<=69,"B+",IF(Q20<=79,"A",IF(Q20<=89,"A+","O")))))))) -> F | U20: =R20*S20 -> 0 | Z20: =SUM(W20:X20) -> 0 | AA20: 3 | AB20: =IF(X20<=17,"0",IF(Z20<=39,"0",IF(Z20<=49,"4",IF(Z20<=54,"5",IF(Z20<=59,"6",IF(Z20<=69,"7",IF(Z20<=79,"8",IF(Z20<=89,"9","10")))))))) -> 0 | AC20: =IF(X20<=17,"F",IF(Z20<=39,"F",IF(Z20<=49,"P",IF(Z20<=54,"C",IF(Z20<=59,"B",IF(Z20<=69,"B+",IF(Z20<=79,"A",IF(Z20<=89,"A+","O")))))))) -> F | AD20: =AA20*AB20 -> 0 | AI20: =SUM(AF20:AG20) -> 0 | AJ20: 3 | AK20: =IF(AG20<=17,"0",IF(AI20<=39,"0",IF(AI20<=49,"4",IF(AI20<=54,"5",IF(AI20<=59,"6",IF(AI20<=69,"7",IF(AI20<=79,"8",IF(AI20<=89,"9","10")))))))) -> 0 | AL20: =IF(AG20<=17,"F",IF(AI20<=39,"F",IF(AI20<=49,"P",IF(AI20<=54,"C",IF(AI20<=59,"B",IF(AI20<=69,"B+",IF(AI20<=79,"A",IF(AI20<=89,"A+","O")))))))) -> F | AM20: =AJ20*AK20 -> 0 | AR20: =(AO20+AP20) -> 0 | AS20: 3 | AT20: =IF(AP20<=17,"0",IF(AR20<=39,"0",IF(AR20<=49,"4",IF(AR20<=54,"5",IF(AR20<=59,"6",IF(AR20<=69,"7",IF(AR20<=79,"8",IF(AR20<=89,"9","10")))))))) -> 0 | AU20: =IF(AP20<=17,"F",IF(AR20<=39,"F",IF(AR20<=49,"P",IF(AR20<=54,"C",IF(AR20<=59,"B",IF(AR20<=69,"B+",IF(AR20<=79,"A",IF(AR20<=89,"A+","O")))))))) -> F | AV20: =AS20*AT20 -> 0 | BA20: =(AX20+AY20) -> 0 | BB20: 1 | BC20: =IF(AY20<=17,"0",IF(BA20<=39,"0",IF(BA20<=49,"4",IF(BA20<=54,"5",IF(BA20<=59,"6",IF(BA20<=69,"7",IF(BA20<=79,"8",IF(BA20<=89,"9","10")))))))) -> 0 | BD20: =IF(AY20<=17,"F",IF(BA20<=39,"F",IF(BA20<=49,"P",IF(BA20<=54,"C",IF(BA20<=59,"B",IF(BA20<=69,"B+",IF(BA20<=79,"A",IF(BA20<=89,"A+","O")))))))) -> F | BE20: =BB20*BC20 -> 0 | BF20: Balake Kannada | BJ20: =(BG20+BH20) -> 0 | BK20: 1 | BL20: =IF(BH20<=17,"0",IF(BJ20<=39,"0",IF(BJ20<=49,"4",IF(BJ20<=54,"5",IF(BJ20<=59,"6",IF(BJ20<=69,"7",IF(BJ20<=79,"8",IF(BJ20<=89,"9","10")))))))) -> 0 | BM20: =IF(BH20<=17,"F",IF(BJ20<=39,"F",IF(BJ20<=49,"P",IF(BJ20<=54,"C",IF(BJ20<=59,"B",IF(BJ20<=69,"B+",IF(BJ20<=79,"A",IF(BJ20<=89,"A+","O")))))))) -> F | BN20: =BK20*BL20 -> 0 | BS20: =(BP20+BQ20) -> 0 | BT20: 1 | BU20: =IF(BQ20<=17,"0",IF(BS20<=39,"0",IF(BS20<=49,"4",IF(BS20<=54,"5",IF(BS20<=59,"6",IF(BS20<=69,"7",IF(BS20<=79,"8",IF(BS20<=89,"9","10")))))))) -> 0 | BV20: =IF(BQ20<=17,"F",IF(BS20<=39,"F",IF(BS20<=49,"P",IF(BS20<=54,"C",IF(BS20<=59,"B",IF(BS20<=69,"B+",IF(BS20<=79,"A",IF(BS20<=89,"A+","O")))))))) -> F | BW20: =BT20*BU20 -> 0 | BZ20: =L20+U20+AD20+AM20+AV20+BE20+BN20+BW20 -> 0 | CA20: =BZ20/20 -> 0 | CB20: =IF(CA20<4,"F",IF(BV20="F","F",IF(BM20="F","F",IF(BD20="F","F",IF(AU20="F","F",IF(AL20="F","F",IF(AC20="F","F",IF(T20="F","F",IF(K20="F","F",IF(CA20<=5,"C",IF(CA20<6,"B",IF(CA20<7,"B+",IF(CA20<8,"A",IF(CA20<=9,"A+","O")))))))))))))) -> F | CC20: =CA20*9.5 -> 0 | CE20: =SUM(BS20,BJ20,BA20,AR20,AI20,Z20,Q20,H20) -> 0 | CF20: =(CE20/800)*100 -> 0 | CI20: =IF(CA20<=4,"F",IF(CA20<=6,"PASS",IF(CA20<=6.5,"SC",IF(CA20<=7.5,"FC",IF(CA20<="10","FCD"))))) -> F
A21: =A20+1 -> 14 | B21: 1BI23CD014 | C21: DARSHITH C M | D21: D | H21: =SUM(E21:F21) -> 0 | I21: 4 | J21: =IF(F21<=17,"0",IF(H21<=39,"0",IF(H21<=49,"4",IF(H21<=54,"5",IF(H21<=59,"6",IF(H21<=69,"7",IF(H21<=79,"8",IF(H21<=89,"9","10")))))))) -> 0 | K21: =IF(F21<=17,"F",IF(H21<=39,"F",IF(H21<=49,"P",IF(H21<=54,"C",IF(H21<=59,"B",IF(H21<=69,"B+",IF(H21<=79,"A",IF(H21<=89,"A+","O")))))))) -> F | L21: =I21*J21 -> 0 | Q21: =SUM(N21:O21) -> 0 | R21: 4 | S21: =IF(O21<=17,"0",IF(Q21<=39,"4",IF(Q21<=49,"4",IF(Q21<=54,"5",IF(Q21<=59,"6",IF(Q21<=69,"7",IF(Q21<=79,"8",IF(Q21<=89,"9","10")))))))) -> 0 | T21: =IF(O21<=17,"F",IF(Q21<=39,"F",IF(Q21<=49,"P",IF(Q21<=54,"C",IF(Q21<=59,"B",IF(Q21<=69,"B+",IF(Q21<=79,"A",IF(Q21<=89,"A+","O")))))))) -> F | U21: =R21*S21 -> 0 | Z21: =SUM(W21:X21) -> 0 | AA21: 3 | AB21: =IF(X21<=17,"0",IF(Z21<=39,"0",IF(Z21<=49,"4",IF(Z21<=54,"5",IF(Z21<=59,"6",IF(Z21<=69,"7",IF(Z21<=79,"8",IF(Z21<=89,"9","10")))))))) -> 0 | AC21: =IF(X21<=17,"F",IF(Z21<=39,"F",IF(Z21<=49,"P",IF(Z21<=54,"C",IF(Z21<=59,"B",IF(Z21<=69,"B+",IF(Z21<=79,"A",IF(Z21<=89,"A+","O")))))))) -> F | AD21: =AA21*AB21 -> 0 | AI21: =SUM(AF21:AG21) -> 0 | AJ21: 3 | AK21: =IF(AG21<=17,"0",IF(AI21<=39,"0",IF(AI21<=49,"4",IF(AI21<=54,"5",IF(AI21<=59,"6",IF(AI21<=69,"7",IF(AI21<=79,"8",IF(AI21<=89,"9","10")))))))) -> 0 | AL21: =IF(AG21<=17,"F",IF(AI21<=39,"F",IF(AI21<=49,"P",IF(AI21<=54,"C",IF(AI21<=59,"B",IF(AI21<=69,"B+",IF(AI21<=79,"A",IF(AI21<=89,"A+","O")))))))) -> F | AM21: =AJ21*AK21 -> 0 | AR21: =(AO21+AP21) -> 0 | AS21: 3 | AT21: =IF(AP21<=17,"0",IF(AR21<=39,"0",IF(AR21<=49,"4",IF(AR21<=54,"5",IF(AR21<=59,"6",IF(AR21<=69,"7",IF(AR21<=79,"8",IF(AR21<=89,"9","10")))))))) -> 0 | AU21: =IF(AP21<=17,"F",IF(AR21<=39,"F",IF(AR21<=49,"P",IF(AR21<=54,"C",IF(AR21<=59,"B",IF(AR21<=69,"B+",IF(AR21<=79,"A",IF(AR21<=89,"A+","O")))))))) -> F | AV21: =AS21*AT21 -> 0 | BA21: =(AX21+AY21) -> 0 | BB21: 1 | BC21: =IF(AY21<=17,"0",IF(BA21<=39,"0",IF(BA21<=49,"4",IF(BA21<=54,"5",IF(BA21<=59,"6",IF(BA21<=69,"7",IF(BA21<=79,"8",IF(BA21<=89,"9","10")))))))) -> 0 | BD21: =IF(AY21<=17,"F",IF(BA21<=39,"F",IF(BA21<=49,"P",IF(BA21<=54,"C",IF(BA21<=59,"B",IF(BA21<=69,"B+",IF(BA21<=79,"A",IF(BA21<=89,"A+","O")))))))) -> F | BE21: =BB21*BC21 -> 0 | BF21: Balake Kannada | BJ21: =(BG21+BH21) -> 0 | BK21: 1 | BL21: =IF(BH21<=17,"0",IF(BJ21<=39,"0",IF(BJ21<=49,"4",IF(BJ21<=54,"5",IF(BJ21<=59,"6",IF(BJ21<=69,"7",IF(BJ21<=79,"8",IF(BJ21<=89,"9","10")))))))) -> 0 | BM21: =IF(BH21<=17,"F",IF(BJ21<=39,"F",IF(BJ21<=49,"P",IF(BJ21<=54,"C",IF(BJ21<=59,"B",IF(BJ21<=69,"B+",IF(BJ21<=79,"A",IF(BJ21<=89,"A+","O")))))))) -> F | BN21: =BK21*BL21 -> 0 | BS21: =(BP21+BQ21) -> 0 | BT21: 1 | BU21: =IF(BQ21<=17,"0",IF(BS21<=39,"0",IF(BS21<=49,"4",IF(BS21<=54,"5",IF(BS21<=59,"6",IF(BS21<=69,"7",IF(BS21<=79,"8",IF(BS21<=89,"9","10")))))))) -> 0 | BV21: =IF(BQ21<=17,"F",IF(BS21<=39,"F",IF(BS21<=49,"P",IF(BS21<=54,"C",IF(BS21<=59,"B",IF(BS21<=69,"B+",IF(BS21<=79,"A",IF(BS21<=89,"A+","O")))))))) -> F | BW21: =BT21*BU21 -> 0 | BZ21: =L21+U21+AD21+AM21+AV21+BE21+BN21+BW21 -> 0 | CA21: =BZ21/20 -> 0 | CB21: =IF(CA21<4,"F",IF(BV21="F","F",IF(BM21="F","F",IF(BD21="F","F",IF(AU21="F","F",IF(AL21="F","F",IF(AC21="F","F",IF(T21="F","F",IF(K21="F","F",IF(CA21<=5,"C",IF(CA21<6,"B",IF(CA21<7,"B+",IF(CA21<8,"A",IF(CA21<=9,"A+","O")))))))))))))) -> F | CC21: =CA21*9.5 -> 0 | CE21: =SUM(BS21,BJ21,BA21,AR21,AI21,Z21,Q21,H21) -> 0 | CF21: =(CE21/800)*100 -> 0 | CI21: =IF(CA21<=4,"F",IF(CA21<=6,"PASS",IF(CA21<=6.5,"SC",IF(CA21<=7.5,"FC",IF(CA21<="10","FCD"))))) -> F
A22: =A21+1 -> 15 | B22: 1BI23CD015 | C22: DEEKSHA R S | D22: D | H22: =SUM(E22:F22) -> 0 | I22: 4 | J22: =IF(F22<=17,"0",IF(H22<=39,"0",IF(H22<=49,"4",IF(H22<=54,"5",IF(H22<=59,"6",IF(H22<=69,"7",IF(H22<=79,"8",IF(H22<=89,"9","10")))))))) -> 0 | K22: =IF(F22<=17,"F",IF(H22<=39,"F",IF(H22<=49,"P",IF(H22<=54,"C",IF(H22<=59,"B",IF(H22<=69,"B+",IF(H22<=79,"A",IF(H22<=89,"A+","O")))))))) -> F | L22: =I22*J22 -> 0 | Q22: =SUM(N22:O22) -> 0 | R22: 4 | S22: =IF(O22<=17,"0",IF(Q22<=39,"4",IF(Q22<=49,"4",IF(Q22<=54,"5",IF(Q22<=59,"6",IF(Q22<=69,"7",IF(Q22<=79,"8",IF(Q22<=89,"9","10")))))))) -> 0 | T22: =IF(O22<=17,"F",IF(Q22<=39,"F",IF(Q22<=49,"P",IF(Q22<=54,"C",IF(Q22<=59,"B",IF(Q22<=69,"B+",IF(Q22<=79,"A",IF(Q22<=89,"A+","O")))))))) -> F | U22: =R22*S22 -> 0 | Z22: =SUM(W22:X22) -> 0 | AA22: 3 | AB22: =IF(X22<=17,"0",IF(Z22<=39,"0",IF(Z22<=49,"4",IF(Z22<=54,"5",IF(Z22<=59,"6",IF(Z22<=69,"7",IF(Z22<=79,"8",IF(Z22<=89,"9","10")))))))) -> 0 | AC22: =IF(X22<=17,"F",IF(Z22<=39,"F",IF(Z22<=49,"P",IF(Z22<=54,"C",IF(Z22<=59,"B",IF(Z22<=69,"B+",IF(Z22<=79,"A",IF(Z22<=89,"A+","O")))))))) -> F | AD22: =AA22*AB22 -> 0 | AI22: =SUM(AF22:AG22) -> 0 | AJ22: 3 | AK22: =IF(AG22<=17,"0",IF(AI22<=39,"0",IF(AI22<=49,"4",IF(AI22<=54,"5",IF(AI22<=59,"6",IF(AI22<=69,"7",IF(AI22<=79,"8",IF(AI22<=89,"9","10")))))))) -> 0 | AL22: =IF(AG22<=17,"F",IF(AI22<=39,"F",IF(AI22<=49,"P",IF(AI22<=54,"C",IF(AI22<=59,"B",IF(AI22<=69,"B+",IF(AI22<=79,"A",IF(AI22<=89,"A+","O")))))))) -> F | AM22: =AJ22*AK22 -> 0 | AR22: =(AO22+AP22) -> 0 | AS22: 3 | AT22: =IF(AP22<=17,"0",IF(AR22<=39,"0",IF(AR22<=49,"4",IF(AR22<=54,"5",IF(AR22<=59,"6",IF(AR22<=69,"7",IF(AR22<=79,"8",IF(AR22<=89,"9","10")))))))) -> 0 | AU22: =IF(AP22<=17,"F",IF(AR22<=39,"F",IF(AR22<=49,"P",IF(AR22<=54,"C",IF(AR22<=59,"B",IF(AR22<=69,"B+",IF(AR22<=79,"A",IF(AR22<=89,"A+","O")))))))) -> F | AV22: =AS22*AT22 -> 0 | BA22: =(AX22+AY22) -> 0 | BB22: 1 | BC22: =IF(AY22<=17,"0",IF(BA22<=39,"0",IF(BA22<=49,"4",IF(BA22<=54,"5",IF(BA22<=59,"6",IF(BA22<=69,"7",IF(BA22<=79,"8",IF(BA22<=89,"9","10")))))))) -> 0 | BD22: =IF(AY22<=17,"F",IF(BA22<=39,"F",IF(BA22<=49,"P",IF(BA22<=54,"C",IF(BA22<=59,"B",IF(BA22<=69,"B+",IF(BA22<=79,"A",IF(BA22<=89,"A+","O")))))))) -> F | BE22: =BB22*BC22 -> 0 | BF22: Samskrutika Kannada | BJ22: =(BG22+BH22) -> 0 | BK22: 1 | BL22: =IF(BH22<=17,"0",IF(BJ22<=39,"0",IF(BJ22<=49,"4",IF(BJ22<=54,"5",IF(BJ22<=59,"6",IF(BJ22<=69,"7",IF(BJ22<=79,"8",IF(BJ22<=89,"9","10")))))))) -> 0 | BM22: =IF(BH22<=17,"F",IF(BJ22<=39,"F",IF(BJ22<=49,"P",IF(BJ22<=54,"C",IF(BJ22<=59,"B",IF(BJ22<=69,"B+",IF(BJ22<=79,"A",IF(BJ22<=89,"A+","O")))))))) -> F | BN22: =BK22*BL22 -> 0 | BS22: =(BP22+BQ22) -> 0 | BT22: 1 | BU22: =IF(BQ22<=17,"0",IF(BS22<=39,"0",IF(BS22<=49,"4",IF(BS22<=54,"5",IF(BS22<=59,"6",IF(BS22<=69,"7",IF(BS22<=79,"8",IF(BS22<=89,"9","10")))))))) -> 0 | BV22: =IF(BQ22<=17,"F",IF(BS22<=39,"F",IF(BS22<=49,"P",IF(BS22<=54,"C",IF(BS22<=59,"B",IF(BS22<=69,"B+",IF(BS22<=79,"A",IF(BS22<=89,"A+","O")))))))) -> F | BW22: =BT22*BU22 -> 0 | BZ22: =L22+U22+AD22+AM22+AV22+BE22+BN22+BW22 -> 0 | CA22: =BZ22/20 -> 0 | CB22: =IF(CA22<4,"F",IF(BV22="F","F",IF(BM22="F","F",IF(BD22="F","F",IF(AU22="F","F",IF(AL22="F","F",IF(AC22="F","F",IF(T22="F","F",IF(K22="F","F",IF(CA22<=5,"C",IF(CA22<6,"B",IF(CA22<7,"B+",IF(CA22<8,"A",IF(CA22<=9,"A+","O")))))))))))))) -> F | CC22: =CA22*9.5 -> 0 | CE22: =SUM(BS22,BJ22,BA22,AR22,AI22,Z22,Q22,H22) -> 0 | CF22: =(CE22/800)*100 -> 0 | CI22: =IF(CA22<=4,"F",IF(CA22<=6,"PASS",IF(CA22<=6.5,"SC",IF(CA22<=7.5,"FC",IF(CA22<="10","FCD"))))) -> F
A23: =A22+1 -> 16 | B23: 1BI23CD016 | C23: ESHWAR R J | D23: D | H23: =SUM(E23:F23) -> 0 | I23: 4 | J23: =IF(F23<=17,"0",IF(H23<=39,"0",IF(H23<=49,"4",IF(H23<=54,"5",IF(H23<=59,"6",IF(H23<=69,"7",IF(H23<=79,"8",IF(H23<=89,"9","10")))))))) -> 0 | K23: =IF(F23<=17,"F",IF(H23<=39,"F",IF(H23<=49,"P",IF(H23<=54,"C",IF(H23<=59,"B",IF(H23<=69,"B+",IF(H23<=79,"A",IF(H23<=89,"A+","O")))))))) -> F | L23: =I23*J23 -> 0 | Q23: =SUM(N23:O23) -> 0 | R23: 4 | S23: =IF(O23<=17,"0",IF(Q23<=39,"4",IF(Q23<=49,"4",IF(Q23<=54,"5",IF(Q23<=59,"6",IF(Q23<=69,"7",IF(Q23<=79,"8",IF(Q23<=89,"9","10")))))))) -> 0 | T23: =IF(O23<=17,"F",IF(Q23<=39,"F",IF(Q23<=49,"P",IF(Q23<=54,"C",IF(Q23<=59,"B",IF(Q23<=69,"B+",IF(Q23<=79,"A",IF(Q23<=89,"A+","O")))))))) -> F | U23: =R23*S23 -> 0 | Z23: =SUM(W23:X23) -> 0 | AA23: 3 | AB23: =IF(X23<=17,"0",IF(Z23<=39,"0",IF(Z23<=49,"4",IF(Z23<=54,"5",IF(Z23<=59,"6",IF(Z23<=69,"7",IF(Z23<=79,"8",IF(Z23<=89,"9","10")))))))) -> 0 | AC23: =IF(X23<=17,"F",IF(Z23<=39,"F",IF(Z23<=49,"P",IF(Z23<=54,"C",IF(Z23<=59,"B",IF(Z23<=69,"B+",IF(Z23<=79,"A",IF(Z23<=89,"A+","O")))))))) -> F | AD23: =AA23*AB23 -> 0 | AI23: =SUM(AF23:AG23) -> 0 | AJ23: 3 | AK23: =IF(AG23<=17,"0",IF(AI23<=39,"0",IF(AI23<=49,"4",IF(AI23<=54,"5",IF(AI23<=59,"6",IF(AI23<=69,"7",IF(AI23<=79,"8",IF(AI23<=89,"9","10")))))))) -> 0 | AL23: =IF(AG23<=17,"F",IF(AI23<=39,"F",IF(AI23<=49,"P",IF(AI23<=54,"C",IF(AI23<=59,"B",IF(AI23<=69,"B+",IF(AI23<=79,"A",IF(AI23<=89,"A+","O")))))))) -> F | AM23: =AJ23*AK23 -> 0 | AR23: =(AO23+AP23) -> 0 | AS23: 3 | AT23: =IF(AP23<=17,"0",IF(AR23<=39,"0",IF(AR23<=49,"4",IF(AR23<=54,"5",IF(AR23<=59,"6",IF(AR23<=69,"7",IF(AR23<=79,"8",IF(AR23<=89,"9","10")))))))) -> 0 | AU23: =IF(AP23<=17,"F",IF(AR23<=39,"F",IF(AR23<=49,"P",IF(AR23<=54,"C",IF(AR23<=59,"B",IF(AR23<=69,"B+",IF(AR23<=79,"A",IF(AR23<=89,"A+","O")))))))) -> F | AV23: =AS23*AT23 -> 0 | BA23: =(AX23+AY23) -> 0 | BB23: 1 | BC23: =IF(AY23<=17,"0",IF(BA23<=39,"0",IF(BA23<=49,"4",IF(BA23<=54,"5",IF(BA23<=59,"6",IF(BA23<=69,"7",IF(BA23<=79,"8",IF(BA23<=89,"9","10")))))))) -> 0 | BD23: =IF(AY23<=17,"F",IF(BA23<=39,"F",IF(BA23<=49,"P",IF(BA23<=54,"C",IF(BA23<=59,"B",IF(BA23<=69,"B+",IF(BA23<=79,"A",IF(BA23<=89,"A+","O")))))))) -> F | BE23: =BB23*BC23 -> 0 | BF23: Balake Kannada | BJ23: =(BG23+BH23) -> 0 | BK23: 1 | BL23: =IF(BH23<=17,"0",IF(BJ23<=39,"0",IF(BJ23<=49,"4",IF(BJ23<=54,"5",IF(BJ23<=59,"6",IF(BJ23<=69,"7",IF(BJ23<=79,"8",IF(BJ23<=89,"9","10")))))))) -> 0 | BM23: =IF(BH23<=17,"F",IF(BJ23<=39,"F",IF(BJ23<=49,"P",IF(BJ23<=54,"C",IF(BJ23<=59,"B",IF(BJ23<=69,"B+",IF(BJ23<=79,"A",IF(BJ23<=89,"A+","O")))))))) -> F | BN23: =BK23*BL23 -> 0 | BS23: =(BP23+BQ23) -> 0 | BT23: 1 | BU23: =IF(BQ23<=17,"0",IF(BS23<=39,"0",IF(BS23<=49,"4",IF(BS23<=54,"5",IF(BS23<=59,"6",IF(BS23<=69,"7",IF(BS23<=79,"8",IF(BS23<=89,"9","10")))))))) -> 0 | BV23: =IF(BQ23<=17,"F",IF(BS23<=39,"F",IF(BS23<=49,"P",IF(BS23<=54,"C",IF(BS23<=59,"B",IF(BS23<=69,"B+",IF(BS23<=79,"A",IF(BS23<=89,"A+","O")))))))) -> F | BW23: =BT23*BU23 -> 0 | BZ23: =L23+U23+AD23+AM23+AV23+BE23+BN23+BW23 -> 0 | CA23: =BZ23/20 -> 0 | CB23: =IF(CA23<4,"F",IF(BV23="F","F",IF(BM23="F","F",IF(BD23="F","F",IF(AU23="F","F",IF(AL23="F","F",IF(AC23="F","F",IF(T23="F","F",IF(K23="F","F",IF(CA23<=5,"C",IF(CA23<6,"B",IF(CA23<7,"B+",IF(CA23<8,"A",IF(CA23<=9,"A+","O")))))))))))))) -> F | CC23: =CA23*9.5 -> 0 | CE23: =SUM(BS23,BJ23,BA23,AR23,AI23,Z23,Q23,H23) -> 0 | CF23: =(CE23/800)*100 -> 0 | CI23: =IF(CA23<=4,"F",IF(CA23<=6,"PASS",IF(CA23<=6.5,"SC",IF(CA23<=7.5,"FC",IF(CA23<="10","FCD"))))) -> F
